Workbook

Sheet 전체교사시간표
A1: 전체교사시간표
A2: 교사 | B2: 시수 | C2: 담임 | D2: 월 | J2: 화 | Q2: 수 | X2: 목 | AE2: 금
D3: 1 | E3: 2 | F3: 3 | G3: 4 | H3: 5 | I3: 6 | J3: 1 | K3: 2 | L3: 3 | M3: 4 | N3: 5 | O3: 6 | P3: 7 | Q3: 1 | R3: 2 | S3: 3 | T3: 4 | U3: 5 | V3: 6 | W3: 7 | X3: 1 | Y3: 2 | Z3: 3 | AA3: 4 | AB3: 5 | AC3: 6 | AD3: 7 | AE3: 1 | AF3: 2 | AG3: 3 | AH3: 4 | AI3: 5 | AJ3: 6 | AK3: 7
A4: 이은주 | B4: 16 | C4: 1-7 | D4: 102_x000D_ 국어 | F4: 107_x000D_ 국어 | H4: 105_x000D_ 국어 | I4: 101_x000D_ 국어 | L4: 106_x000D_ 국어 | M4: 104_x000D_ 국어 | O4: 105_x000D_ 국어 | Q4: 108_x000D_ 국어 | U4: 101_x000D_ 국어 | V4: 창체 | W4: 창체 | Y4: 103_x000D_ 국어 | AB4: 102_x000D_ 국어 | AC4: 106_x000D_ 국어 | AE4: 103_x000D_ 국어 | AG4: 107_x000D_ 국어 | AI4: 104_x000D_ 국어 | AJ4: 108_x000D_ 국어
A5: 도진희 | B5: 16 | C5: 1-1 | D5: 104_x000D_ 국어 | H5: 103_x000D_ 국어 | I5: 106_x000D_ 국어 | J5: 108_x000D_ 국어 | L5: 107_x000D_ 국어 | M5: 102_x000D_ 국어 | O5: 103_x000D_ 국어 | R5: 104_x000D_ 국어 | S5: 105_x000D_ 국어 | V5: 창체 | W5: 창체 | Z5: 107_x000D_ 국어 | AA5: 108_x000D_ 국어 | AC5: 101_x000D_ 국어 | AE5: 101_x000D_ 국어 | AH5: 106_x000D_ 국어 | AJ5: 102_x000D_ 국어 | AK5: 105_x000D_ 국어
A6: 배기연 | B6: 13 | C6: 2-2 | G6: 201_x000D_ 독서 | I6: 202_x000D_ 독서 | K6: 202_x000D_ 독서 | L6: 208_x000D_ 독서 | O6: 205_x000D_ 독서 | P6: 203_x000D_ 독서 | Q6: 201_x000D_ C_문영 | R6: 207_x000D_ 독서 | V6: 창체 | W6: 창체 | X6: 201_x000D_ 독서 | AA6: 204_x000D_ 독서 | AC6: 206_x000D_ 독서 | AH6: 203_x000D_ 독서 | AJ6: 204_x000D_ 독서
A7: 정수진 | B7: 13 | E7: 207_x000D_ 독서 | F7: 204_x000D_ 독서 | H7: 208_x000D_ 독서 | M7: 206_x000D_ 독서 | P7: 201_x000D_ 독서 | R7: 208_x000D_ 독서 | S7: 205_x000D_ 독서 | V7: 창체 | W7: 창체 | X7: 202_x000D_ 독서 | AA7: 203_x000D_ 독서 | AF7: 206_x000D_ 독서 | AG7: 204_x000D_ A_언생 | AI7: 207_x000D_ 독서 | AJ7: 205_x000D_ 독서
A8: 박지빈 | B8: 12 | E8: 203_x000D_ 독서 | F8: 206 독서 | L8: 201_x000D_ C_문영 | N8: 204_x000D_ A_언생 | T8: 204_x000D_ 독서 | V8: 창체 | W8: 창체 | X8: 205_x000D_ 독서 | Z8: 204_x000D_ A_언생 | AA8: 207_x000D_ 독서 | AE8: 201_x000D_ C_문영 | AH8: 201_x000D_ 독서 | AI8: 208_x000D_ 독서 | AK8: 202_x000D_ 독서
A9: 조상희 | B9: 16 | C9: 3-4 | F9: 306_x000D_ K_심국 | G9: 303_x000D_ L_심국 | I9: 302_x000D_ O_심국 | J9: 306_x000D_ K_심국 | K9: 302_x000D_ O_심국 | M9: 303_x000D_ L_심국 | O9: 304_x000D_ M_심국 | P9: 당겨오기 수업 | Q9: 302_x000D_ O_심국 | R9: 303_x000D_ L_심국 | S9: 304_x000D_ M_심국 | U9: 당겨오기 수업 | V9: 창체 | W9: 창체 | X9: 306_x000D_ K_심국 | Y9: 302_x000D_ O_심국 | AB9: 304_x000D_ M_심국 | AD9: 당겨오기 수업 | AE9: 306_x000D_ K_심국 | AF9: 303_x000D_ L_심국 | AI9: 304_x000D_ M_심국
A10: 박소은 | B10: 16 | C10: 3-5 | D10: 304_x000D_ N_고전 | F10: 305_x000D_ K_고전 | G10: 301_x000D_ L_고전 | J10: 305_x000D_ K_고전 | M10: 301_x000D_ L_고전 | O10: 303_x000D_ M_고전 | P10: 당겨오기 수업 | R10: 301_x000D_ L_고전 | S10: 303_x000D_ M_고전 | T10: 304_x000D_ N_고전 | U10: 당겨오기 수업 | V10: 창체 | W10: 창체 | X10: 305_x000D_ K_고전 | AB10: 303_x000D_ M_고전 | AC10: 304_x000D_ N_고전 | AD10: 당겨오기 수업 | AE10: 305_x000D_ K_고전 | AF10: 301_x000D_ L_고전 | AI10: 303_x000D_ M_고전 | AJ10: 304_x000D_ N_고전
A11: 장정숙 | B11: 14 | C11: 1-2 | E11: 104_x000D_ 수학 | G11: 106_x000D_ 수학 | H11: 102_x000D_ 수학 | J11: 105_x000D_ 수학 | K11: 103_x000D_ 수학 | M11: 107_x000D_ 수학 | Q11: 101_x000D_ 수학 | U11: 102_x000D_ 수학 | V11: 창체 | W11: 창체 | Z11: 101_x000D_ 수학 | AB11: 106_x000D_ 수학 | AD11: 103_x000D_ 수학 | AF11: 104_x000D_ 수학 | AI11: 105_x000D_ 수학 | AJ11: 107_x000D_ 수학
A12: 강언화 | B12: 14 | D12: 101_x000D_ 수학 | E12: 105_x000D_ 수학 | H12: 107_x000D_ 수학 | L12: 102_x000D_ 수학 | N12: 104_x000D_ 수학 | P12: 106_x000D_ 수학 | R12: 103_x000D_ 수학 | U12: 106_x000D_ 수학 | V12: 창체 | W12: 창체 | Z12: 105_x000D_ 수학 | AB12: 104_x000D_ 수학 | AD12: 107_x000D_ 수학 | AG12: 102_x000D_ 수학 | AI12: 101_x000D_ 수학 | AJ12: 103_x000D_ 수학
A13: 이승익 | B13: 15 | C13: 2-3 | D13: 203_x000D_ 미적 | E13: 205_x000D_ 미적 | G13: 204_x000D_ 미적 | I13: 207_x000D_ 미적 | K13: 203_x000D_ 미적 | O13: 204_x000D_ 미적 | P13: 206_x000D_ 미적 | R13: 206_x000D_ 미적 | V13: 창체 | W13: 창체 | X13: 206_x000D_ 미적 | Y13: 205_x000D_ 미적 | AC13: 207_x000D_ 미적 | AF13: 203_x000D_ 미적 | AH13: 205_x000D_ 미적 | AI13: 204_x000D_ 미적 | AK13: 207_x000D_ 미적
A14: 김동춘 | B14: 14 | E14: 208_x000D_ 미적 | F14: 201_x000D_ 미적 | H14: 210(선택4) B_교이 | J14: 210(선텍4) B_교이 | N14: 208_x000D_ 미적 | O14: 202_x000D_ 미적 | R14: 205_x000D_ 미적 | S14: 207_x000D_ 미적 | V14: 창체 | W14: 창체 | X14: 203_x000D_ 미적 | Y14: 208_x000D_ 미적 | AB14: 210(선택4) B_교이 | AD14: 204_x000D_ 미적 | AF14: 208_x000D_ 미적 | AI14: 206_x000D_ 미적
A15: 김이진 | B15: 15 | E15: 304_x000D_ 진로 | F15: 202_x000D_ 미적 | H15: 302_x000D_ 진로 | J15: 309(선택1) K_실수 | L15: 301_x000D_ 진로 | O15: 310(선택2) M_실수 | P15: 당겨오기 수업 | R15: 202_x000D_ 미적 | T15: 201_x000D_ 미적 | U15: 당겨오기 수업 | V15: 창체 | W15: 창체 | Y15: 201_x000D_ 미적 | Z15: 303_x000D_ 진로 | AB15: 310(선택2) M_실수 | AD15: 당겨오기 수업 | AE15: 309(선택1) K_실수 | AF15: 201_x000D_ 미적 | AH15: 305_x000D_ P_심리 | AI15: 202_x000D_ 미적
A16: 장성훈 | B16: 13 | F16: 309(선택1) K_실수 | H16: 203_x000D_ B_기하 | J16: 203_x000D_ B_기하 | L16: 210(선택4) C_기하 | N16: 201_x000D_ A_기하 | P16: 당겨오기 수업 | Q16: 210(선택4) C_기하 | S16: 310(선택2) M_실수 | U16: 당겨오기 수업 | V16: 창체 | W16: 창체 | X16: 309(선택1) K_실수 | Z16: 201_x000D_ A_기하 | AB16: 203_x000D_ B_기하 | AD16: 당겨오기 수업 | AE16: 210(선택4) C_기하 | AG16: 201_x000D_ A_기하 | AI16: 310(선택2) M_실수
A17: 조낙원 | B17: 13 | F17: 307_x000D_ K_심수1 | G17: 108_x000D_ 수학 | I17: 304_x000D_ O_심수1 | J17: 307_x000D_ K_심수1 | K17: 304_x000D_ O_심수1 | N17: 305_x000D_ 진로 | P17: 당겨오기 수업 | Q17: 304_x000D_ O_심수1 | S17: 108_x000D_ 수학 | U17: 당겨오기 수업 | V17: 창체 | W17: 창체 | X17: 307_x000D_ K_심수1 | Y17: 304_x000D_ O_심수1 | AB17: 108_x000D_ 수학 | AD17: 당겨오기 수업 | AE17: 307_x000D_ K_심수1 | AH17: 108_x000D_ 수학
A18: 서종민 | B18: 16 | C18: 3-1 | D18: 306_x000D_ N_심수2 | G18: 304_x000D_ L_심수2 | I18: 305_x000D_ O_심수2 | K18: 305_x000D_ O_심수2 | M18: 304_x000D_ L_심수2 | N18: 202_x000D_ A_기하 | P18: 당겨오기 수업 | Q18: 305_x000D_ O_심수2 | R18: 304_x000D_ L_심수2 | T18: 306_x000D_ N_심수2 | U18: 당겨오기 수업 | V18: 창체 | W18: 창체 | Y18: 305_x000D_ O_심수2 | Z18: 202_x000D_ A_기하 | AC18: 306_x000D_ N_심수2 | AD18: 당겨오기 수업 | AF18: 304_x000D_ L_심수2 | AG18: 202_x000D_ A_기하 | AH18: 304_x000D_ P_논리 | AJ18: 306_x000D_ N_심수2
A19: 김수빈 | B19: 15 | C19: 1-6 | E19: 106_x000D_ 영어 | H19: 101_x000D_ 영어 | I19: 105_x000D_ 영어 | K19: 104_x000D_ 영어 | O19: 102_x000D_ 영어 | Q19: 102_x000D_ 영어 | R19: 108_x000D_ 영어 | T19: 107_x000D_ 영어 | V19: 창체 | W19: 창체 | X19: 103_x000D_ 영어 | AA19: 105_x000D_ 영어 | AB19: 107_x000D_ 영어 | AE19: 104_x000D_ 영어 | AG19: 106_x000D_ 영어 | AH19: 103_x000D_ 영어 | AJ19: 101_x000D_ 영어
A20: 성아름 | B20: 15 | E20: 107_x000D_ 영어 | H20: 108_x000D_ 영어 | K20: 101_x000D_ 영어 | L20: 307_x000D_ 진로 | N20: 103_x000D_ 영어 | O20: 108_x000D_ 영어 | P20: 당겨오기 수업 | Q20: 106_x000D_ 영어 | R20: 306_x000D_ L_심영 | U20: 105_x000D_ 영어 | V20: 창체 | W20: 창체 | Y20: 108_x000D_ 영어 | AA20: 102_x000D_ 영어 | AC20: 104_x000D_ 영어 | AD20: 당겨오기 수업 | AE20: 302_x000D_ K_심영 | AH20: 306_x000D_ P_심리 | AK20: 306_x000D_ 진로
A21: 곽선근 | B21: 15 | E21: 103_x000D_ 영어 | G21: 202_x000D_ 영어2 | I21: 204_x000D_ 영어2 | K21: 207_x000D_ 영어2 | M21: 205_x000D_ 영어2 | O21: 206_x000D_ 영어2 | R21: 203_x000D_ 영어2 | U21: 104_x000D_ 영어 | V21: 창체 | W21: 창체 | X21: 101_x000D_ 영어 | Z21: 106_x000D_ 영어 | AD21: 201_x000D_ 영어2 | AE21: 107_x000D_ 영어 | AF21: 102_x000D_ 영어 | AH21: 307_x000D_ P_심리 | AJ21: 105_x000D_ 영어
A22: 전은영 | B22: 15 | C22: 2-4 | D22: 207_x000D_ 영어2 | F22: 205 영어2 | G22: 203 영어2 | I22: 206_x000D_ 영어2 | M22: 202_x000D_ 영어2 | O22: 201_x000D_ 영어2 | S22: 201_x000D_ 영어2 | T22: 205_x000D_ 영어2 | V22: 창체 | W22: 창체 | X22: 207_x000D_ 영어2 | AC22: 204_x000D_ 영어2 | AD22: 206_x000D_ 영어2 | AG22: 208_x000D_ 영어2 | AH22: 204_x000D_ 영어2 | AJ22: 202_x000D_ 영어2 | AK22: 203_x000D_ 영어2
A23: 장지현 | B23: 16 | D23: 305_x000D_ N_심영 | H23: 301_x000D_ 진로 | J23: 308_x000D_ 진로 | K23: 303_x000D_ O_심영 | M23: 208_x000D_ 영어2 | O23: 307_x000D_ M_심영 | P23: 당겨오기 수업 | S23: 204_x000D_ 영어2 | T23: 208_x000D_ 영어2 | U23: 당겨오기 수업 | V23: 창체 | W23: 창체 | X23: 208_x000D_ 영어2 | AA23: 205_x000D_ 영어2 | AC23: 203_x000D_ 영어2 | AD23: 202_x000D_ 영어2 | AF23: 207_x000D_ 영어2 | AH23: 311(선택3) P_교육 | AJ23: 201_x000D_ 영어2 | AK23: 206_x000D_ 영어2
A24: 백지은 | B24: 16 | C24: 3-2 | F24: 302_x000D_ K_심영 | G24: 306_x000D_ L_심영 | I24: 303_x000D_ O_심영 | J24: 302_x000D_ K_심영 | M24: 306_x000D_ L_심영 | P24: 당겨오기 수업 | Q24: 303_x000D_ O_심영 | S24: 307_x000D_ M_심영 | T24: 305_x000D_ N_심영 | U24: 당겨오기 수업 | V24: 창체 | W24: 창체 | X24: 302_x000D_ K_심영 | Y24: 303_x000D_ O_심영 | AB24: 307_x000D_ M_심영 | AC24: 305_x000D_ N_심영 | AD24: 당겨오기 수업 | AF24: 306_x000D_ L_심영 | AH24: 309(선택1) P_교육 | AI24: 307_x000D_ M_심영 | AJ24: 305_x000D_ N_심영
A25: 김주영 | B25: 16 | C25: 2-5 | F25: 105_x000D_ 통과 | H25: 206_x000D_ B_역학 | J25: 206_x000D_ B_역학 | L25: 207_x000D_ C_역학 | N25: 205_x000D_ A_역학 | P25: 104_x000D_ 통과 | Q25: 207_x000D_ C_역학 | R25: 106_x000D_ 통과 | U25: 103_x000D_ 통과 | V25: 창체 | W25: 창체 | Z25: 205_x000D_ A_역학 | AB25: 206_x000D_ B_역학 | AD25: 101_x000D_ 통과 | AE25: 207_x000D_ C_역학 | AG25: 205_x000D_ A_역학 | AI25: 102_x000D_ 통과 | AK25: 107_x000D_ 통과
A26: 정혁준 | B26: 15 | D26: 301_x000D_ N_물실 | F26: 303_x000D_ K_물실 | G26: 305_x000D_ L_융과 | J26: 303_x000D_ K_물실 | M26: 305_x000D_ L_융과 | P26: 당겨오기 수업 | R26: 305_x000D_ L_융과 | T26: 301_x000D_ N_물실 | U26: 108_x000D_ 통과 | V26: 창체 | W26: 창체 | X26: 303_x000D_ K_물실 | AA26: 302_x000D_ 진로 | AC26: 301_x000D_ N_물실 | AD26: 당겨오기 수업 | AE26: 303_x000D_ K_물실 | AF26: 305_x000D_ L_융과 | AH26: 301_x000D_ P_환경 | AJ26: 301_x000D_ N_물실
A27: 류효정 | B27: 15 | D27: 307_x000D_ N_융과 | H27: 207_x000D_ B_화학 | J27: 207_x000D_ B_화학 | L27: 103_x000D_ 과탐실 | N27: 108_x000D_ 과탐실 | P27: 101_x000D_ 과탐실 | Q27: 105_x000D_ 과탐실 | S27: 104_x000D_ 과탐실 | T27: 307_x000D_ N_융과 | U27: 당겨오기 수업 | V27: 창체 | W27: 창체 | AB27: 207_x000D_ B_화학 | AC27: 307_x000D_ N_융과 | AD27: 당겨오기 수업 | AF27: 106_x000D_ 과탐실 | AH27: 107_x000D_ 과탐실 | AJ27: 307_x000D_ N_융과 | AK27: 102_x000D_ 과탐실
A28: 류정심 | B28: 16 | C28: 1-3 | D28: 103_x000D_ 통과 | F28: 101_x000D_ 통과 | G28: 311(선택3) L_화실 | I28: 107_x000D_ 통과 | K28: 108_x000D_ 통과 | M28: 311(선택3) L_화실 | O28: 306_x000D_ M_화실 | P28: 당겨오기 수업 | R28: 311(선택3) L_화실 | S28: 306_x000D_ M_화실 | U28: 당겨오기 수업 | V28: 창체 | W28: 창체 | Y28: 106_x000D_ 통과 | Z28: 102_x000D_ 통과 | AB28: 306_x000D_ M_화실 | AD28: 당겨오기 수업 | AE28: 105_x000D_ 통과 | AF28: 311(선택3) L_화실 | AI28: 306_x000D_ M_화실 | AK28: 104_x000D_ 통과
A29: 장가영 | B29: 15 | D29: 108_x000D_ 통과 | H29: 202_x000D_ B_생명 | J29: 202_x000D_ B_생명 | L29: 203_x000D_ C_생명 | N29: 102_x000D_ 통과 | Q29: 203_x000D_ C_생명 | T29: 101_x000D_ 통과 | V29: 창체 | W29: 창체 | Y29: 107_x000D_ 통과 | AA29: 104_x000D_ 통과 | AB29: 202_x000D_ B_생명 | AD29: 105_x000D_ 통과 | AE29: 203_x000D_ C_생명 | AF29: 103_x000D_ 통과 | AH29: 302_x000D_ P_환경 | AJ29: 106_x000D_ 통과
A30: 고수연 | B30: 15 | C30: 3-6 | D30: 310(선택2) N_생과실 | F30: 304_x000D_ K_생태 | G30: 302_x000D_ L_생태 | L30: 205_x000D_ C_생물 | O30: 301_x000D_ M_생과실 | P30: 당겨오기 수업 | Q30: 205_x000D_ C_생물 | S30: 301 M_생과실 | T30: 310(선택2) N_생과실 | U30: 당겨오기 수업 | V30: 창체 | W30: 창체 | X30: 304_x000D_ K_생태 | AB30: 301_x000D_ M_생과실 | AC30: 310(선택2) N_생과실 | AD30: 당겨오기 수업 | AE30: 205_x000D_ C_생물 | AF30: 302_x000D_ L_생태 | AI30: 301_x000D_ M_생과실 | AJ30: 310(선택2) N_생과실
A31: 최정윤 | B31: 9 | H31: 106_x000D_ 통과 | I31: 104_x000D_ 통과 | N31: 105_x000D_ 통과 | S31: 107_x000D_ 통과 | T31: 102_x000D_ 통과 | V31: 창체 | W31: 창체 | Z31: 108_x000D_ 통과 | AB31: 103_x000D_ 통과 | AE31: 304_x000D_ K_생태 | AG31: 101_x000D_ 통과
A32: 민수빈 | B32: 6 | J32: 304_x000D_ K_생태 | K32: 208_x000D_ 기후 | M32: 302_x000D_ L_생태 | P32: 당겨오기 수업 | Q32: 208_x000D_ 기후 | R32: 302_x000D_ L_생태 | S32: 208_x000D_ 기후 | U32: 당겨오기 수업 | V32: 창체 | W32: 창체 | AD32: 당겨오기 수업
A33: 박미라 | B33: 15 | D33: 303_x000D_ N_지구2 | G33: 307_x000D_ L_지구실 | I33: 301_x000D_ O_지구실 | K33: 301_x000D_ O_지구실 | M33: 307_x000D_ L_지구실 | N33: 303_x000D_ 진로 | P33: 당겨오기 수업 | Q33: 301_x000D_ O_지구실 | R33: 307_x000D_ L_지구실 | T33: 303_x000D_ N_지구2 | U33: 당겨오기 수업 | V33: 창체 | W33: 창체 | Y33: 301_x000D_ O_지구실 | AC33: 303_x000D_ N_지구2 | AD33: 당겨오기 수업 | AF33: 307_x000D_ L_지구실 | AH33: 303_x000D_ P_보건 | AJ33: 303_x000D_ N_지구2 | AK33: 304_x000D_ 진로
A34: 정지윤 | B34: 17 | C34: 2-6 | E34: 101_x000D_ 통사 | F34: 106_x000D_ 통사 | H34: 205_x000D_ B_현사윤 | I34: 103_x000D_ 통사 | J34: 205_x000D_ B_현사윤 | L34: 204_x000D_ C_현사윤 | N34: 206_x000D_ A_현사윤 | P34: 105_x000D_ 통사 | Q34: 204_x000D_ C_현사윤 | T34: 108_x000D_ 통사 | V34: 창체 | W34: 창체 | Y34: 102_x000D_ 통사 | Z34: 206_x000D_ A_현사윤 | AB34: 205_x000D_ B_현사윤 | AE34: 204_x000D_ C_현사윤 | AG34: 206_x000D_ A_현사윤 | AI34: 107_x000D_ 통사 | AJ34: 104_x000D_ 통사
A35: 이수민 | B35: 15 | C35: 3-7 | F35: 301_x000D_ K_고윤 | I35: 306_x000D_ O_고윤 | J35: 301_x000D_ K_고윤 | K35: 306_x000D_ O_고윤 | N35: 207_x000D_ A_현사윤 | O35: 302_x000D_ M_고윤 | P35: 당겨오기 수업 | Q35: 306_x000D_ O_고윤 | S35: 302_x000D_ M_고윤 | U35: 당겨오기 수업 | V35: 창체 | W35: 창체 | X35: 301_x000D_ K_고윤 | Y35: 306_x000D_ O_고윤 | Z35: 207_x000D_ A_현사윤 | AB35: 302_x000D_ M_고윤 | AD35: 당겨오기 수업 | AE35: 301_x000D_ K_고윤 | AG35: 207_x000D_ A_현사윤 | AI35: 302_x000D_ M_고윤
A36: 김예민 | B36: 15 | C36: 2-1 | G36: 105_x000D_ 통사 | H36: 204_x000D_ B_세지 | J36: 204_x000D_ B_세지 | L36: 104_x000D_ 통사 | N36: 106_x000D_ 통사 | P36: 102_x000D_ 통사 | R36: 101_x000D_ 통사 | S36: 103_x000D_ 통사 | V36: 창체 | W36: 창체 | X36: 104_x000D_ 통사 | AB36: 204_x000D_ B_세지 | AC36: 107_x000D_ 통사 | AE36: 102_x000D_ 통사 | AG36: 103_x000D_ 통사 | AI36: 108_x000D_ 통사 | AK36: 101_x000D_ 통사
A37: 김광진 | B37: 9 | D37: 311(선택3) N_비교 | I37: 310(선택2) O_비교 | K37: 310(선택2) O_비교 | M37: 108_x000D_ 통사 | P37: 당겨오기 수업 | Q37: 310(선택2) O_비교 | T37: 311(선택3) N_비교 | U37: 당겨오기 수업 | V37: 창체 | W37: 창체 | Y37: 310(선택2) O_비교 | AC37: 311(선택3) N_비교 | AD37: 당겨오기 수업 | AJ37: 311(선택3) N_비교
A38: 이경민 | B38: 14 | D38: 107_x000D_ 통사 | E38: 108_x000D_ 통사 | H38: 201_x000D_ B_법사 | J38: 201_x000D_ B_법사 | L38: 202_x000D_ C_법사 | P38: 당겨오기 수업 | Q38: 202_x000D_ C_법사 | S38: 305_x000D_ M_현대 | T38: 302_x000D_ N_현대 | U38: 당겨오기 수업 | V38: 창체 | W38: 창체 | AB38: 201_x000D_ B_법사 | AC38: 302_x000D_ N_현대 | AD38: 당겨오기 수업 | AE38: 202_x000D_ C_법사 | AF38: 105_x000D_ 통사 | AI38: 305_x000D_ M_현대 | AK38: 106_x000D_ 통사
A39: 오경희 | B39: 7 | Q39: 107_x000D_ 통사 | S39: 102_x000D_ 통사 | T39: 104_x000D_ 통사 | V39: 창체 | W39: 창체 | Y39: 101_x000D_ 통사 | Z39: 103_x000D_ 통사 | AB39: 105_x000D_ 통사 | AD39: 106_x000D_ 통사
A40: 전진주 | B40: 17 | D40: 302_x000D_ N_현대 | F40: 108_x000D_ 국사1 | I40: 102_x000D_ 국사1 | J40: 106_x000D_ 국사1 | K40: 102_x000D_ 국사1 | M40: 105_x000D_ 국사1 | O40: 104_x000D_ 국사1 | R40: 107_x000D_ 국사1 | S40: 101_x000D_ 국사1 | V40: 창체 | W40: 창체 | X40: 107_x000D_ 국사1 | AA40: 101_x000D_ 국사1 | AC40: 103_x000D_ 국사1 | AD40: 104_x000D_ 국사1 | AE40: 108_x000D_ 국사1 | AH40: 105_x000D_ 국사1 | AI40: 106_x000D_ 국사1 | AK40: 103_x000D_ 국사1
...

Sheet 개인별 교사시간표
B2: 2026학년도 2학기 시간표
E3: 교사명 | F3: 이은주
C4: 월 | D4: 화 | E4: 수 | F4: 목 | G4: 금
B5: 1 | C5: =VLOOKUP($F$3,전체교사시간표!$A$4:$AK$63,4,0) -> 102_x000D_ 국어 | D5: =VLOOKUP($F$3,전체교사시간표!$A$4:$AK$63,10,0) -> 0 | E5: =VLOOKUP($F$3,전체교사시간표!$A$4:$AK$63,17,0) -> 108_x000D_ 국어 | F5: =VLOOKUP($F$3,전체교사시간표!$A$4:$AK$63,24,0) -> 0 | G5: =VLOOKUP($F$3,전체교사시간표!$A$4:$AK$63,31,0) -> 103_x000D_ 국어
B6: 2 | C6: =VLOOKUP($F$3,전체교사시간표!$A$4:$AJ$63,5,0) -> 0 | D6: =VLOOKUP($F$3,전체교사시간표!$A$4:$AK$63,11,0) -> 0 | E6: =VLOOKUP($F$3,전체교사시간표!$A$4:$AK$63,18,0) -> 0 | F6: =VLOOKUP($F$3,전체교사시간표!$A$4:$AK$63,25,0) -> 103_x000D_ 국어 | G6: =VLOOKUP($F$3,전체교사시간표!$A$4:$AK$63,32,0) -> 0
B7: 3 | C7: =VLOOKUP($F$3,전체교사시간표!$A$4:$AK$63,6,0) -> 107_x000D_ 국어 | D7: =VLOOKUP($F$3,전체교사시간표!$A$4:$AK$63,12,0) -> 106_x000D_ 국어 | E7: =VLOOKUP($F$3,전체교사시간표!$A$4:$AK$63,19,0) -> 0 | F7: =VLOOKUP($F$3,전체교사시간표!$A$4:$AK$63,26,0) -> 0 | G7: =VLOOKUP($F$3,전체교사시간표!$A$4:$AK$63,33,0) -> 107_x000D_ 국어
B8: 4 | C8: =VLOOKUP($F$3,전체교사시간표!$A$4:$AK$63,7,0) -> 0 | D8: =VLOOKUP($F$3,전체교사시간표!$A$4:$AK$63,13,0) -> 104_x000D_ 국어 | E8: =VLOOKUP($F$3,전체교사시간표!$A$4:$AK$63,20,0) -> 0 | F8: =VLOOKUP($F$3,전체교사시간표!$A$4:$AK$63,27,0) -> 0 | G8: =VLOOKUP($F$3,전체교사시간표!$A$4:$AK$63,34,0) -> 0
B9: 5 | C9: =VLOOKUP($F$3,전체교사시간표!$A$4:$AK$63,8,0) -> 105_x000D_ 국어 | D9: =VLOOKUP($F$3,전체교사시간표!$A$4:$AK$63,14,0) -> 0 | E9: =VLOOKUP($F$3,전체교사시간표!$A$4:$AK$63,21,0) -> 101_x000D_ 국어 | F9: =VLOOKUP($F$3,전체교사시간표!$A$4:$AK$63,28,0) -> 102_x000D_ 국어 | G9: =VLOOKUP($F$3,전체교사시간표!$A$4:$AK$63,35,0) -> 104_x000D_ 국어
B10: 6 | C10: =VLOOKUP($F$3,전체교사시간표!$A$4:$AK$63,9,0) -> 101_x000D_ 국어 | D10: =VLOOKUP($F$3,전체교사시간표!$A$4:$AK$63,15,0) -> 105_x000D_ 국어 | E10: =VLOOKUP($F$3,전체교사시간표!$A$4:$AK$63,22,0) -> 창체 | F10: =VLOOKUP($F$3,전체교사시간표!$A$4:$AK$63,29,0) -> 106_x000D_ 국어 | G10: =VLOOKUP($F$3,전체교사시간표!$A$4:$AK$63,36,0) -> 108_x000D_ 국어
B11: 7 | D11: =VLOOKUP($F$3,전체교사시간표!$A$4:$AK$63,16,0) -> 0 | E11: =VLOOKUP($F$3,전체교사시간표!$A$4:$AK$63,23,0) -> 창체 | F11: =VLOOKUP($F$3,전체교사시간표!$A$4:$AK$63,30,0) -> 0 | G11: =VLOOKUP($F$3,전체교사시간표!$A$4:$AK$63,37,0) -> 0

Sheet 전체학급시간표(교사용)
A1: 전체학급시간표
A2: 학급 | B2: 월 | H2: 화 | O2: 수 | V2: 목 | AC2: 금
B3: 1 | C3: 2 | D3: 3 | E3: 4 | F3: 5 | G3: 6 | H3: 1 | I3: 2 | J3: 3 | K3: 4 | L3: 5 | M3: 6 | N3: 7 | O3: 1 | P3: 2 | Q3: 3 | R3: 4 | S3: 5 | T3: 6 | U3: 7 | V3: 1 | W3: 2 | X3: 3 | Y3: 4 | Z3: 5 | AA3: 6 | AB3: 7 | AC3: 1 | AD3: 2 | AE3: 3 | AF3: 4 | AG3: 5 | AH3: 6 | AI3: 7
A4: 1학년1반 | B4: 수학_x000D_ 강언화 | C4: 통사_x000D_ 정지윤 | D4: 통과_x000D_ 류정심 | E4: 음악_x000D_ 손혜영 | F4: 영어_x000D_ 김수빈 | G4: 국어_x000D_ 이은주 | H4: 국사1_x000D_ 송영림 | I4: 영어_x000D_ 성아름 | J4: 진학_x000D_ 이금순 | K4: 체육_x000D_ 박은총 | L4: 정보_x000D_ 이호철 | M4: 정보_x000D_ 이호철 | N4: 과탐실_x000D_ 류효정 | O4: 수학_x000D_ 장정숙 | P4: 통사_x000D_ 김예민 | Q4: 국사1_x000D_ 전진주 | R4: 통과_x000D_ 장가영 | S4: 국어_x000D_ 이은주 | T4: 창체 | U4: 창체 | V4: 영어_x000D_ 곽선근 | W4: 통사_x000D_ 오경희 | X4: 수학_x000D_ 장정숙 | Y4: 국사1_x000D_ 전진주 | Z4: 체육_x000D_ 이수환 | AA4: 국어_x000D_ 도진희 | AB4: 통과_x000D_ 김주영 | AC4: 국어_x000D_ 도진희 | AD4: 음악_x000D_ 손혜영 | AE4: 통과_x000D_ 최정윤 | AF4: 정보_x000D_ 김규강 | AG4: 수학_x000D_ 강언화 | AH4: 영어_x000D_ 김수빈 | AI4: 통사_x000D_ 김예민
A5: 1학년2반 | B5: 국어_x000D_ 이은주 | C5: 정보_x000D_ 김규강 | D5: 체육_x000D_ 이수환 | E5: 진학_x000D_ 이금순 | F5: 수학_x000D_ 장정숙 | G5: 국사1_x000D_ 전진주 | H5: 음악_x000D_ 손혜영 | I5: 국사1_x000D_ 전진주 | J5: 수학_x000D_ 강언화 | K5: 국어_x000D_ 도진희 | L5: 통과_x000D_ 장가영 | M5: 영어_x000D_ 김수빈 | N5: 통사_x000D_ 김예민 | O5: 영어_x000D_ 김수빈 | P5: 음악_x000D_ 손혜영 | Q5: 통사_x000D_ 오경희 | R5: 통과_x000D_ 최정윤 | S5: 수학_x000D_ 장정숙 | T5: 창체 | U5: 창체 | V5: 체육_x000D_ 박은총 | W5: 통사_x000D_ 정지윤 | X5: 통과_x000D_ 류정심 | Y5: 영어_x000D_ 성아름 | Z5: 국어_x000D_ 이은주 | AA5: 정보_x000D_ 이호철 | AB5: 정보_x000D_ 이호철 | AC5: 통사_x000D_ 김예민 | AD5: 영어_x000D_ 곽선근 | AE5: 수학_x000D_ 강언화 | AF5: 국사1_x000D_ 송영림 | AG5: 통과_x000D_ 김주영 | AH5: 국어_x000D_ 도진희 | AI5: 과탐실_x000D_ 류효정
A6: 1학년3반 | B6: 통과_x000D_ 류정심 | C6: 영어_x000D_ 곽선근 | D6: 정보_x000D_ 이호철 | E6: 정보_x000D_ 이호철 | F6: 국어_x000D_ 도진희 | G6: 통사_x000D_ 정지윤 | H6: 체육_x000D_ 박은총 | I6: 수학_x000D_ 장정숙 | J6: 과탐실_x000D_ 류효정 | K6: 정보_x000D_ 김규강 | L6: 영어_x000D_ 성아름 | M6: 국어_x000D_ 도진희 | N6: 음악_x000D_ 손혜영 | O6: 체육_x000D_ 이수환 | P6: 수학_x000D_ 강언화 | Q6: 통사_x000D_ 김예민 | R6: 국사1_x000D_ 송영림 | S6: 통과_x000D_ 김주영 | T6: 창체 | U6: 창체 | V6: 영어_x000D_ 김수빈 | W6: 국어_x000D_ 이은주 | X6: 통사_x000D_ 오경희 | Y6: 진학_x000D_ 이금순 | Z6: 통과_x000D_ 최정윤 | AA6: 국사1_x000D_ 전진주 | AB6: 수학_x000D_ 장정숙 | AC6: 국어_x000D_ 이은주 | AD6: 통과_x000D_ 장가영 | AE6: 통사_x000D_ 김예민 | AF6: 영어_x000D_ 김수빈 | AG6: 음악_x000D_ 손혜영 | AH6: 수학_x000D_ 강언화 | AI6: 국사1_x000D_ 전진주
A7: 1학년4반 | B7: 국어_x000D_ 도진희 | C7: 수학_x000D_ 장정숙 | D7: 정보_x000D_ 김규강 | E7: 체육_x000D_ 이수환 | F7: 음악_x000D_ 손혜영 | G7: 통과_x000D_ 최정윤 | H7: 체육_x000D_ 신광현 | I7: 영어_x000D_ 김수빈 | J7: 통사_x000D_ 김예민 | K7: 국어_x000D_ 이은주 | L7: 수학_x000D_ 강언화 | M7: 국사1_x000D_ 전진주 | N7: 통과_x000D_ 김주영 | O7: 국사1_x000D_ 송영림 | P7: 국어_x000D_ 도진희 | Q7: 과탐실_x000D_ 류효정 | R7: 통사_x000D_ 오경희 | S7: 영어_x000D_ 곽선근 | T7: 창체 | U7: 창체 | V7: 통사_x000D_ 김예민 | W7: 음악_x000D_ 손혜영 | X7: 진학_x000D_ 이금순 | Y7: 통과_x000D_ 장가영 | Z7: 수학_x000D_ 강언화 | AA7: 영어_x000D_ 성아름 | AB7: 국사1_x000D_ 전진주 | AC7: 영어_x000D_ 김수빈 | AD7: 수학_x000D_ 장정숙 | AE7: 정보_x000D_ 이호철 | AF7: 정보_x000D_ 이호철 | AG7: 국어_x000D_ 이은주 | AH7: 통사_x000D_ 정지윤 | AI7: 통과_x000D_ 류정심
A8: 1학년5반 | B8: 체육_x000D_ 신광현 | C8: 수학_x000D_ 강언화 | D8: 통과_x000D_ 김주영 | E8: 통사_x000D_ 김예민 | F8: 국어_x000D_ 이은주 | G8: 영어_x000D_ 김수빈 | H8: 수학_x000D_ 장정숙 | I8: 체육_x000D_ 이수환 | J8: 음악_x000D_ 손혜영 | K8: 국사1_x000D_ 전진주 | L8: 통과_x000D_ 최정윤 | M8: 국어_x000D_ 이은주 | N8: 통사_x000D_ 정지윤 | O8: 과탐실_x000D_ 류효정 | P8: 진학_x000D_ 이금순 | Q8: 국어_x000D_ 도진희 | R8: 음악_x000D_ 손혜영 | S8: 영어_x000D_ 성아름 | T8: 창체 | U8: 창체 | V8: 정보_x000D_ 이호철 | W8: 정보_x000D_ 이호철 | X8: 수학_x000D_ 강언화 | Y8: 영어_x000D_ 김수빈 | Z8: 통사_x000D_ 오경희 | AA8: 국사1_x000D_ 송영림 | AB8: 통과_x000D_ 장가영 | AC8: 통과_x000D_ 류정심 | AD8: 통사_x000D_ 이경민 | AE8: 정보_x000D_ 김규강 | AF8: 국사1_x000D_ 전진주 | AG8: 수학_x000D_ 장정숙 | AH8: 영어_x000D_ 곽선근 | AI8: 국어_x000D_ 도진희
A9: 1학년6반 | B9: 음악_x000D_ 손혜영 | C9: 영어_x000D_ 김수빈 | D9: 통사_x000D_ 정지윤 | E9: 수학_x000D_ 장정숙 | F9: 통과_x000D_ 최정윤 | G9: 국어_x000D_ 도진희 | H9: 국사1_x000D_ 전진주 | I9: 정보_x000D_ 김규강 | J9: 국어_x000D_ 이은주 | K9: 진학_x000D_ 이금순 | L9: 통사_x000D_ 김예민 | M9: 체육_x000D_ 신광현 | N9: 수학_x000D_ 강언화 | O9: 영어_x000D_ 성아름 | P9: 통과_x000D_ 김주영 | Q9: 정보_x000D_ 이호철 | R9: 정보_x000D_ 이호철 | S9: 수학_x000D_ 강언화 | T9: 창체 | U9: 창체 | V9: 음악_x000D_ 손혜영 | W9: 통과_x000D_ 류정심 | X9: 영어_x000D_ 곽선근 | Y9: 국사1_x000D_ 송영림 | Z9: 수학_x000D_ 장정숙 | AA9: 국어_x000D_ 이은주 | AB9: 통사_x000D_ 오경희 | AC9: 체육_x000D_ 이수환 | AD9: 과탐실_x000D_ 류효정 | AE9: 영어_x000D_ 김수빈 | AF9: 국어_x000D_ 도진희 | AG9: 국사1_x000D_ 전진주 | AH9: 통과_x000D_ 장가영 | AI9: 통사_x000D_ 이경민
A10: 1학년7반 | B10: 통사_x000D_ 이경민 | C10: 영어_x000D_ 성아름 | D10: 국어_x000D_ 이은주 | E10: 정보_x000D_ 김규강 | F10: 수학_x000D_ 강언화 | G10: 통과_x000D_ 류정심 | H10: 정보_x000D_ 이호철 | I10: 정보_x000D_ 이호철 | J10: 국어_x000D_ 도진희 | K10: 수학_x000D_ 장정숙 | L10: 음악_x000D_ 손혜영 | M10: 국사1_x000D_ 송영림 | N10: 체육_x000D_ 신광현 | O10: 통사_x000D_ 오경희 | P10: 국사1_x000D_ 전진주 | Q10: 통과_x000D_ 최정윤 | R10: 영어_x000D_ 김수빈 | S10: 체육_x000D_ 이수환 | T10: 창체 | U10: 창체 | V10: 국사1_x000D_ 전진주 | W10: 통과_x000D_ 장가영 | X10: 국어_x000D_ 도진희 | Y10: 음악_x000D_ 손혜영 | Z10: 영어_x000D_ 김수빈 | AA10: 통사_x000D_ 김예민 | AB10: 수학_x000D_ 강언화 | AC10: 영어_x000D_ 곽선근 | AD10: 진학_x000D_ 이금순 | AE10: 국어_x000D_ 이은주 | AF10: 과탐실_x000D_ 류효정 | AG10: 통사_x000D_ 정지윤 | AH10: 수학_x000D_ 장정숙 | AI10: 통과_x000D_ 김주영
A11: 1학년8반 | B11: 통과_x000D_ 장가영 | C11: 통사_x000D_ 이경민 | D11: 국사1_x000D_ 전진주 | E11: 수학_x000D_ 조낙원 | F11: 영어_x000D_ 성아름 | G11: 정보_x000D_ 이호철 | H11: 국어_x000D_ 도진희 | I11: 통과_x000D_ 류정심 | J11: 정보_x000D_ 김규강 | K11: 통사_x000D_ 김광진 | L11: 과탐실_x000D_ 류효정 | M11: 영어_x000D_ 성아름 | N11: 체육_x000D_ 이수환 | O11: 국어_x000D_ 이은주 | P11: 영어_x000D_ 김수빈 | Q11: 수학_x000D_ 조낙원 | R11: 통사_x000D_ 정지윤 | S11: 통과_x000D_ 정혁준 | T11: 창체 | U11: 창체 | V11: 국사1_x000D_ 송영림 | W11: 영어_x000D_ 성아름 | X11: 통과_x000D_ 최정윤 | Y11: 국어_x000D_ 도진희 | Z11: 수학_x000D_ 조낙원 | AA11: 음악_x000D_ 손혜영 | AB11: 체육_x000D_ 이수환 | AC11: 국사1_x000D_ 전진주 | AD11: 정보_x000D_ 김규강 | AE11: 음악_x000D_ 손혜영 | AF11: 수학_x000D_ 조낙원 | AG11: 통사_x000D_ 김예민 | AH11: 국어_x000D_ 이은주 | AI11: 진학_x000D_ 이금순
A12: 2학년1반 | B12: D_일어_x000D_ 도숙희 | C12: D_일어_x000D_ 도숙희 | D12: 미적_x000D_ 김동춘 | E12: 독서_x000D_ 배기연 | F12: B_법사_x000D_ 이경민 | G12: 미술_x000D_ 박영환 | H12: B_법사_x000D_ 이경민 | I12: 미술_x000D_ 박영환 | J12: C_문영_x000D_ 박지빈 | K12: 스포2_x000D_ 강은일 | L12: A_기하_x000D_ 장성훈 | M12: 영어2_x000D_ 전은영 | N12: 독서_x000D_ 정수진 | O12: C_문영_x000D_ 배기연 | P12: 국사2_x000D_ 김가향 | Q12: 영어2_x000D_ 전은영 | R12: 미적_x000D_ 김이진 | S12: _x000D_ | T12: 창체 | U12: 창체 | V12: 독서_x000D_ 배기연 | W12: 미적_x000D_ 김이진 | X12: A_기하_x000D_ 장성훈 | Y12: D_일어_x000D_ 이다영 | Z12: B_법사_x000D_ 이경민 | AA12: 국사2_x000D_ 김가향 | AB12: 영어2_x000D_ 곽선근 | AC12: C_문영_x000D_ 박지빈 | AD12: 미적_x000D_ 김이진 | AE12: A_기하_x000D_ 장성훈 | AF12: 독서_x000D_ 박지빈 | AG12: 스포2_x000D_ 이수환 | AH12: 영어2_x000D_ 장지현 | AI12: 국사2_x000D_ 정윤희
A13: 2학년2반 | B13: D_일어_x000D_ 이다영 | C13: D_일어_x000D_ 이다영 | D13: 미적_x000D_ 김이진 | E13: 영어2_x000D_ 곽선근 | F13: B_생명_x000D_ 장가영 | G13: 독서_x000D_ 배기연 | H13: B_생명_x000D_ 장가영 | I13: 독서_x000D_ 배기연 | J13: C_법사_x000D_ 이경민 | K13: 영어2_x000D_ 전은영 | L13: A_기하_x000D_ 서종민 | M13: 미적_x000D_ 김동춘 | N13: 국사2_x000D_ 정윤희 | O13: C_법사_x000D_ 이경민 | P13: 미적_x000D_ 김이진 | Q13: 미술_x000D_ 박영환 | R13: 스포2_x000D_ 강은일 | S13: _x000D_ | T13: 창체 | U13: 창체 | V13: 독서_x000D_ 정수진 | W13: 국사2_x000D_ 김가향 | X13: A_기하_x000D_ 서종민 | Y13: D_일어_x000D_ 도숙희 | Z13: B_생명_x000D_ 장가영 | AA13: 미술_x000D_ 박영환 | AB13: 영어2_x000D_ 장지현 | AC13: C_법사_x000D_ 이경민 | AD13: 국사2_x000D_ 김가향 | AE13: A_기하_x000D_ 서종민 | AF13: 스포2_x000D_ 이수환 | AG13: 미적_x000D_ 김이진 | AH13: 영어2_x000D_ 전은영 | AI13: 독서_x000D_ 박지빈
A14: 2학년3반 | B14: 미적_x000D_ 이승익 | C14: 독서_x000D_ 박지빈 | D14: 국사2 정윤희 | E14: 영어2 전은영 | F14: B_기하_x000D_ 장성훈 | G14: 일어 도숙희 | H14: B_기하_x000D_ 장성훈 | I14: 미적_x000D_ 이승익 | J14: C_생명_x000D_ 장가영 | K14: 미술_x000D_ 박영환 | L14: A_세계_x000D_ 정윤희 | M14: 일어_x000D_ 도숙희 | N14: 독서_x000D_ 배기연 | O14: C_생명_x000D_ 장가영 | P14: 영어2_x000D_ 곽선근 | Q14: 스포2_x000D_ 강은일 | R14: 국사2_x000D_ 김가향 | S14: _x000D_ | T14: 창체 | U14: 창체 | V14: 미적_x000D_ 김동춘 | W14: 스포2_x000D_ 이수환 | X14: A_세계_x000D_ 정윤희 | Y14: 독서_x000D_ 정수진 | Z14: B_기하_x000D_ 장성훈 | AA14: 영어2_x000D_ 장지현 | AB14: 국사2_x000D_ 김가향 | AC14: C_생명_x000D_ 장가영 | AD14: 미적_x000D_ 이승익 | AE14: A_세계_x000D_ 정윤희 | AF14: 독서_x000D_ 배기연 | AG14: 미술_x000D_ 박영환 | AH14: 일어_x000D_ 이다영 | AI14: 영어2_x000D_ 전은영
A15: 2학년4반 | B15: 미술_x000D_ 박영환 | C15: 국사2_x000D_ 김가향 | D15: 독서_x000D_ 정수진 | E15: 미적_x000D_ 이승익 | F15: B_세지_x000D_ 김예민 | G15: 영어2_x000D_ 곽선근 | H15: B_세지_x000D_ 김예민 | I15: 일어_x000D_ 도숙희 | J15: C_현사윤 정지윤 | K15: 국사2_x000D_ 김가향 | L15: A_언생_x000D_ 박지빈 | M15: 미적_x000D_ 이승익 | N15: 미술_x000D_ 박영환 | O15: C_현사윤 정지윤 | P15: 스포2_x000D_ 강은일 | Q15: 영어2_x000D_ 장지현 | R15: 독서_x000D_ 박지빈 | S15: _x000D_ | T15: 창체 | U15: 창체 | V15: 일어_x000D_ 도숙희 | W15: 국사2_x000D_ 정윤희 | X15: A_언생_x000D_ 박지빈 | Y15: 독서_x000D_ 배기연 | Z15: B_세지_x000D_ 김예민 | AA15: 영어2_x000D_ 전은영 | AB15: 미적_x000D_ 김동춘 | AC15: C_현사윤 정지윤 | AD15: 스포2_x000D_ 이수환 | AE15: A_언생_x000D_ 정수진 | AF15: 영어2_x000D_ 전은영 | AG15: 미적_x000D_ 이승익 | AH15: 독서_x000D_ 배기연 | AI15: 일어_x000D_ 이다영
... A19: 2학년8반 | B19: 국사2_x000D_ 정윤희 | C19: 미적_x000D_ 김동춘 | D19: 독어_x000D_ 박태호 | E19: 독어_x000D_ 박태호 | F19: 독서_x000D_ 정수진 | G19: 운동_x000D_ 강은일 | H19: 미술_x000D_ 이경진 | I19: 기후_x000D_ 민수빈 | J19: 독서_x000D_ 배기연 | K19: 영어2_x000D_ 장지현 | L19: 미적_x000D_ 김동춘 | M19: 스포2_x000D_ 강은일 | N19: 스경기_x000D_ 강은일 | O19: 기후_x000D_ 민수빈 | P19: 독서_x000D_ 정수진 | Q19: 기후_x000D_ 민수빈 | R19: 영어2_x000D_ 장지현 | S19: _x000D_ | T19: 창체 | U19: 창체 | V19: 영어2_x000D_ 장지현 | W19: 미적_x000D_ 김동춘 | X19: 독어_x000D_ 박태호 | Y19: 국사2_x000D_ 김가향 | Z19: 미술_x000D_ 이경진 | AA19: 운동_x000D_ 강은일 | AB19: 스경기_x000D_ 강은일 | AC19: 운동_x000D_ 강은일 | AD19: 미적_x000D_ 김동춘 | AE19: 영어2_x000D_ 전은영 | AF19: 국사2_x000D_ 김가향 | AG19: 독서_x000D_ 박지빈 | AH19: 스포2_x000D_ 강은일 | AI19: 스경기_x000D_ 강은일
A20: 멀티 미디어실 | B20: _x000D_ | C20: _x000D_ | D20: _x000D_ | E20: _x000D_ | G20: _x000D_ | I20: _x000D_ | J20: C_인공_x000D_ 이호철 | K20: _x000D_ | L20: _x000D_ | M20: _x000D_ | N20: _x000D_ | O20: C_인공_x000D_ 이호철 | P20: _x000D_ | Q20: _x000D_ | R20: _x000D_ | S20: _x000D_ | T20: 창체 | U20: 창체 | V20: _x000D_ | W20: _x000D_ | X20: _x000D_ | Y20: _x000D_ | AA20: _x000D_ | AB20: _x000D_ | AC20: C_인공_x000D_ 이호철 | AD20: _x000D_ | AE20: _x000D_ | AF20: _x000D_ | AG20: _x000D_ | AH20: _x000D_ | AI20: _x000D_
A21: 선택4실(210) | B21: _x000D_ | C21: _x000D_ | D21: _x000D_ | E21: _x000D_ | F21: B_교이_x000D_ 김동춘 | G21: _x000D_ | H21: B_교이_x000D_ 김동춘 | I21: _x000D_ | J21: C_기하_x000D_ 장성훈 | K21: _x000D_ | L21: A_기초_x000D_ 이수환 | M21: _x000D_ | N21: _x000D_ | O21: C_기하_x000D_ 장성훈 | P21: _x000D_ | Q21: _x000D_ | R21: _x000D_ | S21: _x000D_ | T21: 창체 | U21: 창체 | V21: _x000D_ | W21: _x000D_ | X21: A_기초_x000D_ 강은일 | Y21: _x000D_ | Z21: B_교이_x000D_ 김동춘 | AA21: _x000D_ | AB21: _x000D_ | AC21: C_기하_x000D_ 장성훈 | AD21: _x000D_ | AE21: A_기초_x000D_ 강은일 | AF21: _x000D_ | AG21: _x000D_ | AH21: _x000D_ | AI21: _x000D_
A22: 선택3실(211) | B22: _x000D_ | C22: _x000D_ | D22: _x000D_ | E22: _x000D_ | F22: B_기초_x000D_ 강은일 | G22: _x000D_ | H22: B_기초_x000D_ 이수환 | I22: _x000D_ | J22: _x000D_ | K22: _x000D_ | L22: _x000D_ | M22: _x000D_ | N22: _x000D_ | O22: _x000D_ | P22: _x000D_ | Q22: _x000D_ | R22: _x000D_ | S22: _x000D_ | T22: 창체 | U22: 창체 | V22: _x000D_ | W22: _x000D_ | X22: _x000D_ | Y22: _x000D_ | Z22: B_기초_x000D_ 강은일 | AA22: _x000D_ | AB22: _x000D_ | AC22: _x000D_ | AD22: _x000D_ | AE22: _x000D_ | AF22: _x000D_ | AG22: _x000D_ | AH22: _x000D_ | AI22: _x000D_
A23: 3학년1반 | B23: N_물실_x000D_ 정혁준 | C23: 공강_x000D_ 가상1 | D23: K_고윤_x000D_ 이수민 | E23: L_고전_x000D_ 박소은 | F23: 진로_x000D_ 장지현 | G23: O_지구실 박미라 | H23: K_고윤_x000D_ 이수민 | I23: O_지구실 박미라 | J23: 진로_x000D_ 김이진 | K23: L_고전_x000D_ 박소은 | L23: 국사_x000D_ 송영림 | M23: M_생과실_x000D_ 고수연 | N23: 당겨오기수업 | O23: O_지구실_x000D_ 박미라 | P23: L_고전_x000D_ 박소은 | Q23: M_생과실_x000D_ 고수연 | R23: N_물실_x000D_ 정혁준 | S23: 당겨오기수업 | T23: 창체 | U23: 창체 | V23: K_고윤_x000D_ 이수민 | W23: O_지구실_x000D_ 박미라 | X23: 공강_x000D_ 가상2 | Y23: 스포_x000D_ 박은총 | Z23: M_생과실_x000D_ 고수연 | AA23: N_물실_x000D_ 정혁준 | AB23: 당겨오기수업 | AC23: K_고윤_x000D_ 이수민 | AD23: L_고전_x000D_ 박소은 | AE23: 스포_x000D_ 지청호 | AF23: P_환경_x000D_ 정혁준 | AG23: M_생과실_x000D_ 고수연 | AH23: N_물실_x000D_ 정혁준 | AI23: 미감비_x000D_ 이경진
A24: 3학년2반 | B24: N_현대_x000D_ 전진주 | C24: 스포_x000D_ 지청호 | D24: K_심영_x000D_ 백지은 | E24: L_생태_x000D_ 고수연 | F24: 진로_x000D_ 김이진 | G24: O_심국_x000D_ 조상희 | H24: K_심영_x000D_ 백지은 | I24: O_심국_x000D_ 조상희 | J24: 미감비_x000D_ 이경진 | K24: L_생태_x000D_ 민수빈 | L24: 공강_x000D_ 가상2 | M24: M_고윤_x000D_ 이수민 | N24: 당겨오기수업 | O24: O_심국_x000D_ 조상희 | P24: L_생태_x000D_ 민수빈 | Q24: M_고윤_x000D_ 이수민 | R24: N_현대_x000D_ 이경민 | S24: 당겨오기수업 | T24: 창체 | U24: 창체 | V24: K_심영_x000D_ 백지은 | W24: O_심국_x000D_ 조상희 | X24: 스포_x000D_ 박은총 | Y24: 진로_x000D_ 정혁준 | Z24: M_고윤_x000D_ 이수민 | AA24: N_현대_x000D_ 이경민 | AB24: 당겨오기수업 | AC24: K_심영_x000D_ 성아름 | AD24: L_생태_x000D_ 고수연 | AE24: 공강_x000D_ 가상1 | AF24: P_환경_x000D_ 장가영 | AG24: M_고윤_x000D_ 이수민 | AH24: N_현대_x000D_ 정윤희 | AI24: 국사_x000D_ 송영림
A25: 3학년3반 | B25: N_지구2_x000D_ 박미라 | C25: 미감비_x000D_ 이경진 | D25: K_물실_x000D_ 정혁준 | E25: L_심국_x000D_ 조상희 | F25: 공강_x000D_ 가상2 | G25: O_심영_x000D_ 백지은 | H25: K_물실_x000D_ 정혁준 | I25: O_심영_x000D_ 장지현 | J25: 스포_x000D_ 박은총 | K25: L_심국_x000D_ 조상희 | L25: 진로_x000D_ 박미라 | M25: M_고전_x000D_ 박소은 | N25: 당겨오기수업 | O25: O_심영_x000D_ 백지은 | P25: L_심국_x000D_ 조상희 | Q25: M_고전_x000D_ 박소은 | R25: N_지구2_x000D_ 박미라 | S25: 당겨오기수업 | T25: 창체 | U25: 창체 | V25: K_물실_x000D_ 정혁준 | W25: O_심영_x000D_ 백지은 | X25: 진로_x000D_ 김이진 | Y25: 공강_x000D_ 가상1 | Z25: M_고전_x000D_ 박소은 | AA25: N_지구2_x000D_ 박미라 | AB25: 당겨오기수업 | AC25: K_물실_x000D_ 정혁준 | AD25: L_심국_x000D_ 조상희 | AE25: 국사_x000D_ 송영림 | AF25: P_보건_x000D_ 박미라 | AG25: M_고전_x000D_ 박소은 | AH25: N_지구2_x000D_ 박미라 | AI25: 스포_x000D_ 지청호
A26: 3학년4반 | B26: N_고전_x000D_ 박소은 | C26: 진로_x000D_ 김이진 | D26: K_생태_x000D_ 고수연 | E26: L_심수2_x000D_ 서종민 | F26: 스포_x000D_ 지청호 | G26: O_심수1_x000D_ 조낙원 | H26: K_생태_x000D_ 민수빈 | I26: O_심수1_x000D_ 조낙원 | J26: 공강_x000D_ 가상1 | K26: L_심수2_x000D_ 서종민 | L26: 미감비_x000D_ 이경진 | M26: M_심국_x000D_ 조상희 | N26: 당겨오기수업 | O26: O_심수1_x000D_ 조낙원 | P26: L_심수2_x000D_ 서종민 | Q26: M_심국_x000D_ 조상희 | R26: N_고전_x000D_ 박소은 | S26: 당겨오기수업 | T26: 창체 | U26: 창체 | V26: K_생태_x000D_ 고수연 | W26: O_심수1_x000D_ 조낙원 | X26: 국사_x000D_ 송영림 | Y26: 스포_x000D_ 신광현 | Z26: M_심국_x000D_ 조상희 | AA26: N_고전_x000D_ 박소은 | AB26: 당겨오기수업 | AC26: K_생태_x000D_ 최정윤 | AD26: L_심수2_x000D_ 서종민 | AE26: 공강_x000D_ 가상2 | AF26: P_논리_x000D_ 서종민 | AG26: M_심국_x000D_ 조상희 | AH26: N_고전_x000D_ 박소은 | AI26: 진로_x000D_ 박미라
A27: 3학년5반 | B27: N_심영_x000D_ 장지현 | C27: 국사_x000D_ 송영림 | D27: K_고전_x000D_ 박소은 | E27: L_융과_x000D_ 정혁준 | F27: 미감비_x000D_ 이경진 | G27: O_심수2_x000D_ 서종민 | H27: K_고전_x000D_ 박소은 | I27: O_심수2_x000D_ 서종민 | J27: 스포_x000D_ 지청호 | K27: L_융과_x000D_ 정혁준 | L27: 진로_x000D_ 조낙원 | M27: M_현대_x000D_ 김가향 | N27: 당겨오기수업 | O27: O_심수2_x000D_ 서종민 | P27: L_융과_x000D_ 정혁준 | Q27: M_현대_x000D_ 이경민 | R27: N_심영_x000D_ 백지은 | S27: 당겨오기수업 | T27: 창체 | U27: 창체 | V27: K_고전_x000D_ 박소은 | W27: O_심수2_x000D_ 서종민 | X27: 진로_x000D_ 박영환 | Y27: 공강_x000D_ 가상3 | Z27: M_현대_x000D_ 정윤희 | AA27: N_심영_x000D_ 백지은 | AB27: 당겨오기수업 | AC27: K_고전_x000D_ 박소은 | AD27: L_융과_x000D_ 정혁준 | AE27: 공강_x000D_ 가상4 | AF27: P_심리_x000D_ 김이진 | AG27: M_현대_x000D_ 이경민 | AH27: N_심영_x000D_ 백지은 | AI27: 스포_x000D_ 신광현
A28: 3학년6반 | B28: N_심수2_x000D_ 서종민 | C28: 공강_x000D_ 가상4 | D28: K_심국_x000D_ 조상희 | E28: L_심영_x000D_ 백지은 | F28: 진로_x000D_ 박영환 | G28: O_고윤_x000D_ 이수민 | H28: K_심국_x000D_ 조상희 | I28: O_고윤_x000D_ 이수민 | J28: 국사_x000D_ 송영림 | K28: L_심영_x000D_ 백지은 | L28: 공강_x000D_ 가상3 | M28: M_화실_x000D_ 류정심 | N28: 당겨오기수업 | O28: O_고윤_x000D_ 이수민 | P28: L_심영_x000D_ 성아름 | Q28: M_화실_x000D_ 류정심 | R28: N_심수2_x000D_ 서종민 | S28: 당겨오기수업 | T28: 창체 | U28: 창체 | V28: K_심국_x000D_ 조상희 | W28: O_고윤_x000D_ 이수민 | X28: 미감비_x000D_ 이경진 | Y28: 스포_x000D_ 지청호 | Z28: M_화실_x000D_ 류정심 | AA28: N_심수2_x000D_ 서종민 | AB28: 당겨오기수업 | AC28: K_심국_x000D_ 조상희 | AD28: L_심영_x000D_ 백지은 | AE28: 스포_x000D_ 신광현 | AF28: P_심리_x000D_ 성아름 | AG28: M_화실_x000D_ 류정심 | AH28: N_심수2_x000D_ 서종민 | AI28: 진로_x000D_ 성아름
A29: 3학년7반 | B29: N_융과_x000D_ 류효정 | C29: 공강_x000D_ 가상3 | D29: K_심수1_x000D_ 조낙원 | E29: L_지구실_x000D_ 박미라 | F29: 국사_x000D_ 송영림 | G29: O_일어1_x000D_ 이다영 | H29: K_심수1_x000D_ 조낙원 | I29: O_일어1_x000D_ 이다영 | J29: 진로_x000D_ 성아름 | K29: L_지구실_x000D_ 박미라 | L29: 스포_x000D_ 지청호 | M29: M_심영_x000D_ 장지현 | N29: 당겨오기수업 | O29: O_일어1_x000D_ 이다영 | P29: L_지구실_x000D_ 박미라 | Q29: M_심영_x000D_ 백지은 | R29: N_융과_x000D_ 류효정 | S29: 당겨오기수업 | T29: 창체 | U29: 창체 | V29: K_심수1_x000D_ 조낙원 | W29: O_일어1_x000D_ 이다영 | X29: 스포_x000D_ 신광현 | Y29: 미감비_x000D_ 박영환 | Z29: M_심영_x000D_ 백지은 | AA29: N_융과_x000D_ 류효정 | AB29: 당겨오기수업 | AC29: K_심수1_x000D_ 조낙원 | AD29: L_지구실_x000D_ 박미라 | AE29: 진로_x000D_ 이경진 | AF29: P_심리_x000D_ 곽선근 | AG29: M_심영_x000D_ 백지은 | AH29: N_융과_x000D_ 류효정 | AI29: 공강_x000D_ 가상4
A30: 3학년8반 | B30: 스개론_x000D_ 박승순 | C30: 스경체_x000D_ 신광현 | D30: 미감비_x000D_ 박영환 | E30: 스경체_x000D_ 신광현 | F30: 스경분_x000D_ 박승순 | G30: 스경실_x000D_ 신광현 | H30: 진로_x000D_ 장지현 | I30: 스경분_x000D_ 박승순 | J30: 재활_x000D_ 박승순 | K30: 스경체_x000D_ 신광현 | L30: 스개론_x000D_ 박승순 | M30: 스경분_x000D_ 박승순 | N30: _x000D_ | O30: 스경실_x000D_ 신광현 | P30: 진로_x000D_ 이경진 | Q30: 스경분_x000D_ 박승순 | R30: 스경체_x000D_ 신광현 | S30: 재활_x000D_ 박승순 | T30: 창체 | U30: 창체 | V30: 스경실_x000D_ 신광현 | W30: 재활_x000D_ 박승순 | X30: 공강_x000D_ 가상3 | Y30: 공강_x000D_ 가상4 | Z30: 스개론_x000D_ 박승순 | AA30: 스포_x000D_ 지청호 | AB30: _x000D_ | AC30: 국사_x000D_ 송영림 | AD30: 스포_x000D_ 지청호 | AE30: 공강_x000D_ 가상3 | AF30: P_환경_x000D_ 이경진 | AG30: 재활_x000D_ 박승순 | AH30: 스경실_x000D_ 신광현 | AI30: 스개론_x000D_ 박승순
A31: 선택1실(309) | B31: N_창경_x000D_ 임병율 | C31: _x000D_ | D31: K_실수_x000D_ 장성훈 | E31: L_일어1_x000D_ 이다영 | F31: _x000D_ | G31: O_체전실_x000D_ 지청호 | H31: K_실수_x000D_ 김이진 | I31: O_체전실_x000D_ 박은총 | J31: _x000D_ | K31: L_일어1_x000D_ 이다영 | L31: _x000D_ | M31: M_공학_x000D_ 임병율 | N31: _x000D_ | O31: O_체전실_x000D_ 지청호 | P31: L_일어1_x000D_ 이다영 | Q31: M_공학_x000D_ 임병율 | R31: N_창경_x000D_ 임병율 | S31: _x000D_ | T31: 창체 | U31: 창체 | V31: K_실수_x000D_ 장성훈 | W31: O_체전실_x000D_ 박은총 | X31: _x000D_ | Y31: _x000D_ | Z31: M_공학_x000D_ 임병율 | AA31: N_창경_x000D_ 임병율 | AB31: _x000D_ | AC31: K_실수_x000D_ 김이진 | AD31: L_일어1_x000D_ 이다영 | AE31: _x000D_ | AF31: P_교육_x000D_ 백지은 | AG31: M_공학_x000D_ 임병율 | AH31: N_창경_x000D_ 임병율 | AI31: _x000D_
A32: 선택2실(310) | B32: N_생과실_x000D_ 고수연 | C32: _x000D_ | D32: K_공학_x000D_ 임병율 | E32: L_창경_x000D_ 임병율 | F32: _x000D_ | G32: O_비교_x000D_ 김광진 | H32: K_공학_x000D_ 임병율 | I32: O_비교_x000D_ 김광진 | J32: _x000D_ | K32: L_창경_x000D_ 임병율 | L32: _x000D_ | M32: M_실수_x000D_ 김이진 | N32: _x000D_ | O32: O_비교_x000D_ 김광진 | P32: L_창경_x000D_ 임병율 | Q32: M_실수_x000D_ 장성훈 | R32: N_생과실_x000D_ 고수연 | S32: _x000D_ | T32: 창체 | U32: 창체 | V32: K_공학_x000D_ 임병율 | W32: O_비교_x000D_ 김광진 | X32: _x000D_ | Y32: _x000D_ | Z32: M_실수_x000D_ 김이진 | AA32: N_생과실_x000D_ 고수연 | AB32: _x000D_ | AC32: K_공학_x000D_ 임병율 | AD32: L_창경_x000D_ 임병율 | AE32: _x000D_ | AF32: P_실용_x000D_ 박영환 | AG32: M_실수_x000D_ 장성훈 | AH32: N_생과실_x000D_ 고수연 | AI32: _x000D_
A33: 선택3실(311) | B33: N_비교_x000D_ 김광진 | C33: _x000D_ | D33: _x000D_ | E33: L_화실_x000D_ 류정심 | F33: _x000D_ | G33: _x000D_ | H33: _x000D_ | I33: _x000D_ | J33: _x000D_ | K33: L_화실_x000D_ 류정심 | L33: _x000D_ | M33: _x000D_ | N33: _x000D_ | O33: _x000D_ | P33: L_화실_x000D_ 류정심 | Q33: _x000D_ | R33: N_비교_x000D_ 김광진 | S33: _x000D_ | T33: 창체 | U33: 창체 | V33: _x000D_ | W33: _x000D_ | X33: _x000D_ | Y33: _x000D_ | Z33: _x000D_ | AA33: N_비교_x000D_ 김광진 | AB33: _x000D_ | AC33: _x000D_ | AD33: L_화실_x000D_ 류정심 | AE33: _x000D_ | AF33: P_교육_x000D_ 장지현 | AG33: _x000D_ | AH33: N_비교_x000D_ 김광진 | AI33: _x000D_

Sheet 전체학급시간표(학생용)
A1: 전체학급시간표
A2: 학급 | B2: 월 | H2: 화 | O2: 수 | V2: 목 | AC2: 금
B3: 1 | C3: 2 | D3: 3 | E3: 4 | F3: 5 | G3: 6 | H3: 1 | I3: 2 | J3: 3 | K3: 4 | L3: 5 | M3: 6 | N3: 7 | O3: 1 | P3: 2 | Q3: 3 | R3: 4 | S3: 5 | T3: 6 | U3: 7 | V3: 1 | W3: 2 | X3: 3 | Y3: 4 | Z3: 5 | AA3: 6 | AB3: 7 | AC3: 1 | AD3: 2 | AE3: 3 | AF3: 4 | AG3: 5 | AH3: 6 | AI3: 7
A4: 1학년1반 | B4: 수학_x000D_ 강언화 | C4: 통사_x000D_ 정지윤 | D4: 통과_x000D_ 류정심 | E4: 음악_x000D_ 손혜영 | F4: 영어_x000D_ 김수빈 | G4: 국어_x000D_ 이은주 | H4: 국사1_x000D_ 송영림 | I4: 영어_x000D_ 성아름 | J4: 진학_x000D_ 이금순 | K4: 체육_x000D_ 박은총 | L4: 정보_x000D_ 이호철 | M4: 정보_x000D_ 이호철 | N4: 과탐실_x000D_ 류효정 | O4: 수학_x000D_ 장정숙 | P4: 통사_x000D_ 김예민 | Q4: 국사1_x000D_ 전진주 | R4: 통과_x000D_ 장가영 | S4: 국어_x000D_ 이은주 | T4: 창체 | U4: 창체 | V4: 영어_x000D_ 곽선근 | W4: 통사_x000D_ 오경희 | X4: 수학_x000D_ 장정숙 | Y4: 국사1_x000D_ 전진주 | Z4: 체육_x000D_ 이수환 | AA4: 국어_x000D_ 도진희 | AB4: 통과_x000D_ 김주영 | AC4: 국어_x000D_ 도진희 | AD4: 음악_x000D_ 손혜영 | AE4: 통과_x000D_ 최정윤 | AF4: 정보_x000D_ 김규강 | AG4: 수학_x000D_ 강언화 | AH4: 영어_x000D_ 김수빈 | AI4: 통사_x000D_ 김예민
A5: 1학년2반 | B5: 국어_x000D_ 이은주 | C5: 정보_x000D_ 김규강 | D5: 체육_x000D_ 이수환 | E5: 진학_x000D_ 이금순 | F5: 수학_x000D_ 장정숙 | G5: 국사1_x000D_ 전진주 | H5: 음악_x000D_ 손혜영 | I5: 국사1_x000D_ 전진주 | J5: 수학_x000D_ 강언화 | K5: 국어_x000D_ 도진희 | L5: 통과_x000D_ 장가영 | M5: 영어_x000D_ 김수빈 | N5: 통사_x000D_ 김예민 | O5: 영어_x000D_ 김수빈 | P5: 음악_x000D_ 손혜영 | Q5: 통사_x000D_ 오경희 | R5: 통과_x000D_ 최정윤 | S5: 수학_x000D_ 장정숙 | T5: 창체 | U5: 창체 | V5: 체육_x000D_ 박은총 | W5: 통사_x000D_ 정지윤 | X5: 통과_x000D_ 류정심 | Y5: 영어_x000D_ 성아름 | Z5: 국어_x000D_ 이은주 | AA5: 정보_x000D_ 이호철 | AB5: 정보_x000D_ 이호철 | AC5: 통사_x000D_ 김예민 | AD5: 영어_x000D_ 곽선근 | AE5: 수학_x000D_ 강언화 | AF5: 국사1_x000D_ 송영림 | AG5: 통과_x000D_ 김주영 | AH5: 국어_x000D_ 도진희 | AI5: 과탐실_x000D_ 류효정
A6: 1학년3반 | B6: 통과_x000D_ 류정심 | C6: 영어_x000D_ 곽선근 | D6: 정보_x000D_ 이호철 | E6: 정보_x000D_ 이호철 | F6: 국어_x000D_ 도진희 | G6: 통사_x000D_ 정지윤 | H6: 체육_x000D_ 박은총 | I6: 수학_x000D_ 장정숙 | J6: 과탐실_x000D_ 류효정 | K6: 정보_x000D_ 김규강 | L6: 영어_x000D_ 성아름 | M6: 국어_x000D_ 도진희 | N6: 음악_x000D_ 손혜영 | O6: 체육_x000D_ 이수환 | P6: 수학_x000D_ 강언화 | Q6: 통사_x000D_ 김예민 | R6: 국사1_x000D_ 송영림 | S6: 통과_x000D_ 김주영 | T6: 창체 | U6: 창체 | V6: 영어_x000D_ 김수빈 | W6: 국어_x000D_ 이은주 | X6: 통사_x000D_ 오경희 | Y6: 진학_x000D_ 이금순 | Z6: 통과_x000D_ 최정윤 | AA6: 국사1_x000D_ 전진주 | AB6: 수학_x000D_ 장정숙 | AC6: 국어_x000D_ 이은주 | AD6: 통과_x000D_ 장가영 | AE6: 통사_x000D_ 김예민 | AF6: 영어_x000D_ 김수빈 | AG6: 음악_x000D_ 손혜영 | AH6: 수학_x000D_ 강언화 | AI6: 국사1_x000D_ 전진주
A7: 1학년4반 | B7: 국어_x000D_ 도진희 | C7: 수학_x000D_ 장정숙 | D7: 정보_x000D_ 김규강 | E7: 체육_x000D_ 이수환 | F7: 음악_x000D_ 손혜영 | G7: 통과_x000D_ 최정윤 | H7: 체육_x000D_ 신광현 | I7: 영어_x000D_ 김수빈 | J7: 통사_x000D_ 김예민 | K7: 국어_x000D_ 이은주 | L7: 수학_x000D_ 강언화 | M7: 국사1_x000D_ 전진주 | N7: 통과_x000D_ 김주영 | O7: 국사1_x000D_ 송영림 | P7: 국어_x000D_ 도진희 | Q7: 과탐실_x000D_ 류효정 | R7: 통사_x000D_ 오경희 | S7: 영어_x000D_ 곽선근 | T7: 창체 | U7: 창체 | V7: 통사_x000D_ 김예민 | W7: 음악_x000D_ 손혜영 | X7: 진학_x000D_ 이금순 | Y7: 통과_x000D_ 장가영 | Z7: 수학_x000D_ 강언화 | AA7: 영어_x000D_ 성아름 | AB7: 국사1_x000D_ 전진주 | AC7: 영어_x000D_ 김수빈 | AD7: 수학_x000D_ 장정숙 | AE7: 정보_x000D_ 이호철 | AF7: 정보_x000D_ 이호철 | AG7: 국어_x000D_ 이은주 | AH7: 통사_x000D_ 정지윤 | AI7: 통과_x000D_ 류정심
A8: 1학년5반 | B8: 체육_x000D_ 신광현 | C8: 수학_x000D_ 강언화 | D8: 통과_x000D_ 김주영 | E8: 통사_x000D_ 김예민 | F8: 국어_x000D_ 이은주 | G8: 영어_x000D_ 김수빈 | H8: 수학_x000D_ 장정숙 | I8: 체육_x000D_ 이수환 | J8: 음악_x000D_ 손혜영 | K8: 국사1_x000D_ 전진주 | L8: 통과_x000D_ 최정윤 | M8: 국어_x000D_ 이은주 | N8: 통사_x000D_ 정지윤 | O8: 과탐실_x000D_ 류효정 | P8: 진학_x000D_ 이금순 | Q8: 국어_x000D_ 도진희 | R8: 음악_x000D_ 손혜영 | S8: 영어_x000D_ 성아름 | T8: 창체 | U8: 창체 | V8: 정보_x000D_ 이호철 | W8: 정보_x000D_ 이호철 | X8: 수학_x000D_ 강언화 | Y8: 영어_x000D_ 김수빈 | Z8: 통사_x000D_ 오경희 | AA8: 국사1_x000D_ 송영림 | AB8: 통과_x000D_ 장가영 | AC8: 통과_x000D_ 류정심 | AD8: 통사_x000D_ 이경민 | AE8: 정보_x000D_ 김규강 | AF8: 국사1_x000D_ 전진주 | AG8: 수학_x000D_ 장정숙 | AH8: 영어_x000D_ 곽선근 | AI8: 국어_x000D_ 도진희
A9: 1학년6반 | B9: 음악_x000D_ 손혜영 | C9: 영어_x000D_ 김수빈 | D9: 통사_x000D_ 정지윤 | E9: 수학_x000D_ 장정숙 | F9: 통과_x000D_ 최정윤 | G9: 국어_x000D_ 도진희 | H9: 국사1_x000D_ 전진주 | I9: 정보_x000D_ 김규강 | J9: 국어_x000D_ 이은주 | K9: 진학_x000D_ 이금순 | L9: 통사_x000D_ 김예민 | M9: 체육_x000D_ 신광현 | N9: 수학_x000D_ 강언화 | O9: 영어_x000D_ 성아름 | P9: 통과_x000D_ 김주영 | Q9: 정보_x000D_ 이호철 | R9: 정보_x000D_ 이호철 | S9: 수학_x000D_ 강언화 | T9: 창체 | U9: 창체 | V9: 음악_x000D_ 손혜영 | W9: 통과_x000D_ 류정심 | X9: 영어_x000D_ 곽선근 | Y9: 국사1_x000D_ 송영림 | Z9: 수학_x000D_ 장정숙 | AA9: 국어_x000D_ 이은주 | AB9: 통사_x000D_ 오경희 | AC9: 체육_x000D_ 이수환 | AD9: 과탐실_x000D_ 류효정 | AE9: 영어_x000D_ 김수빈 | AF9: 국어_x000D_ 도진희 | AG9: 국사1_x000D_ 전진주 | AH9: 통과_x000D_ 장가영 | AI9: 통사_x000D_ 이경민
A10: 1학년7반 | B10: 통사_x000D_ 이경민 | C10: 영어_x000D_ 성아름 | D10: 국어_x000D_ 이은주 | E10: 정보_x000D_ 김규강 | F10: 수학_x000D_ 강언화 | G10: 통과_x000D_ 류정심 | H10: 정보_x000D_ 이호철 | I10: 정보_x000D_ 이호철 | J10: 국어_x000D_ 도진희 | K10: 수학_x000D_ 장정숙 | L10: 음악_x000D_ 손혜영 | M10: 국사1_x000D_ 송영림 | N10: 체육_x000D_ 신광현 | O10: 통사_x000D_ 오경희 | P10: 국사1_x000D_ 전진주 | Q10: 통과_x000D_ 최정윤 | R10: 영어_x000D_ 김수빈 | S10: 체육_x000D_ 이수환 | T10: 창체 | U10: 창체 | V10: 국사1_x000D_ 전진주 | W10: 통과_x000D_ 장가영 | X10: 국어_x000D_ 도진희 | Y10: 음악_x000D_ 손혜영 | Z10: 영어_x000D_ 김수빈 | AA10: 통사_x000D_ 김예민 | AB10: 수학_x000D_ 강언화 | AC10: 영어_x000D_ 곽선근 | AD10: 진학_x000D_ 이금순 | AE10: 국어_x000D_ 이은주 | AF10: 과탐실_x000D_ 류효정 | AG10: 통사_x000D_ 정지윤 | AH10: 수학_x000D_ 장정숙 | AI10: 통과_x000D_ 김주영
A11: 1학년8반 | B11: 통과_x000D_ 장가영 | C11: 통사_x000D_ 이경민 | D11: 국사1_x000D_ 전진주 | E11: 수학_x000D_ 조낙원 | F11: 영어_x000D_ 성아름 | G11: 정보_x000D_ 이호철 | H11: 국어_x000D_ 도진희 | I11: 통과_x000D_ 류정심 | J11: 정보_x000D_ 김규강 | K11: 통사_x000D_ 김광진 | L11: 과탐실_x000D_ 류효정 | M11: 영어_x000D_ 성아름 | N11: 체육_x000D_ 이수환 | O11: 국어_x000D_ 이은주 | P11: 영어_x000D_ 김수빈 | Q11: 수학_x000D_ 조낙원 | R11: 통사_x000D_ 정지윤 | S11: 통과_x000D_ 정혁준 | T11: 창체 | U11: 창체 | V11: 국사1_x000D_ 송영림 | W11: 영어_x000D_ 성아름 | X11: 통과_x000D_ 최정윤 | Y11: 국어_x000D_ 도진희 | Z11: 수학_x000D_ 조낙원 | AA11: 음악_x000D_ 손혜영 | AB11: 체육_x000D_ 이수환 | AC11: 국사1_x000D_ 전진주 | AD11: 정보_x000D_ 김규강 | AE11: 음악_x000D_ 손혜영 | AF11: 수학_x000D_ 조낙원 | AG11: 통사_x000D_ 김예민 | AH11: 국어_x000D_ 이은주 | AI11: 진학_x000D_ 이금순
A12: 2학년1반 | B12: 이동수업D | C12: 이동수업D | D12: 미적_x000D_ 김동춘 | E12: 독서_x000D_ 배기연 | F12: 이동수업B | G12: 미술_x000D_ 박영환 | H12: 이동수업B | I12: 미술_x000D_ 박영환 | J12: 이동수업C | K12: 스포2_x000D_ 강은일 | L12: 이동수업A | M12: 영어2_x000D_ 전은영 | N12: 독서_x000D_ 정수진 | O12: 이동수업C | P12: 국사2_x000D_ 김가향 | Q12: 영어2_x000D_ 전은영 | R12: 미적_x000D_ 김이진 | S12: _x000D_ | T12: 창체 | U12: 창체 | V12: 독서_x000D_ 배기연 | W12: 미적_x000D_ 김이진 | X12: 이동수업A | Y12: 이동수업D | Z12: 이동수업B | AA12: 국사2_x000D_ 김가향 | AB12: 영어2_x000D_ 곽선근 | AC12: 이동수업C | AD12: 미적_x000D_ 김이진 | AE12: 이동수업A | AF12: 독서_x000D_ 박지빈 | AG12: 스포2_x000D_ 이수환 | AH12: 영어2_x000D_ 장지현 | AI12: 국사2_x000D_ 정윤희
A13: 2학년2반 | B13: 이동수업D | C13: 이동수업D | D13: 미적_x000D_ 김이진 | E13: 영어2_x000D_ 곽선근 | F13: 이동수업B | G13: 독서_x000D_ 배기연 | H13: 이동수업B | I13: 독서_x000D_ 배기연 | J13: 이동수업C | K13: 영어2_x000D_ 전은영 | L13: 이동수업A | M13: 미적_x000D_ 김동춘 | N13: 국사2_x000D_ 정윤희 | O13: 이동수업C | P13: 미적_x000D_ 김이진 | Q13: 미술_x000D_ 박영환 | R13: 스포2_x000D_ 강은일 | S13: _x000D_ | T13: 창체 | U13: 창체 | V13: 독서_x000D_ 정수진 | W13: 국사2_x000D_ 김가향 | X13: 이동수업A | Y13: 이동수업D | Z13: 이동수업B | AA13: 미술_x000D_ 박영환 | AB13: 영어2_x000D_ 장지현 | AC13: 이동수업C | AD13: 국사2_x000D_ 김가향 | AE13: 이동수업A | AF13: 스포2_x000D_ 이수환 | AG13: 미적_x000D_ 김이진 | AH13: 영어2_x000D_ 전은영 | AI13: 독서_x000D_ 박지빈
A14: 2학년3반 | B14: 미적_x000D_ 이승익 | C14: 독서_x000D_ 박지빈 | D14: 국사2 정윤희 | E14: 영어2 전은영 | F14: 이동수업B | G14: 일어 도숙희 | H14: 이동수업B | I14: 미적_x000D_ 이승익 | J14: 이동수업C | K14: 미술_x000D_ 박영환 | L14: 이동수업A | M14: 일어_x000D_ 도숙희 | N14: 독서_x000D_ 배기연 | O14: 이동수업C | P14: 영어2_x000D_ 곽선근 | Q14: 스포2_x000D_ 강은일 | R14: 국사2_x000D_ 김가향 | S14: _x000D_ | T14: 창체 | U14: 창체 | V14: 미적_x000D_ 김동춘 | W14: 스포2_x000D_ 이수환 | X14: 이동수업A | Y14: 독서_x000D_ 정수진 | Z14: 이동수업B | AA14: 영어2_x000D_ 장지현 | AB14: 국사2_x000D_ 김가향 | AC14: 이동수업C | AD14: 미적_x000D_ 이승익 | AE14: 이동수업A | AF14: 독서_x000D_ 배기연 | AG14: 미술_x000D_ 박영환 | AH14: 일어_x000D_ 이다영 | AI14: 영어2_x000D_ 전은영
A15: 2학년4반 | B15: 미술_x000D_ 박영환 | C15: 국사2_x000D_ 김가향 | D15: 독서_x000D_ 정수진 | E15: 미적_x000D_ 이승익 | F15: 이동수업B | G15: 영어2_x000D_ 곽선근 | H15: 이동수업B | I15: 일어_x000D_ 도숙희 | J15: 이동수업C | K15: 국사2_x000D_ 김가향 | L15: 이동수업A | M15: 미적_x000D_ 이승익 | N15: 미술_x000D_ 박영환 | O15: 이동수업C | P15: 스포2_x000D_ 강은일 | Q15: 영어2_x000D_ 장지현 | R15: 독서_x000D_ 박지빈 | S15: _x000D_ | T15: 창체 | U15: 창체 | V15: 일어_x000D_ 도숙희 | W15: 국사2_x000D_ 정윤희 | X15: 이동수업A | Y15: 독서_x000D_ 배기연 | Z15: 이동수업B | AA15: 영어2_x000D_ 전은영 | AB15: 미적_x000D_ 김동춘 | AC15: 이동수업C | AD15: 스포2_x000D_ 이수환 | AE15: 이동수업A | AF15: 영어2_x000D_ 전은영 | AG15: 미적_x000D_ 이승익 | AH15: 독서_x000D_ 배기연 | AI15: 일어_x000D_ 이다영
... A19: 2학년8반 | B19: 국사2_x000D_ 정윤희 | C19: 미적_x000D_ 김동춘 | D19: 독어_x000D_ 박태호 | E19: 독어_x000D_ 박태호 | F19: 독서_x000D_ 정수진 | G19: 운동_x000D_ 강은일 | H19: 미술_x000D_ 이경진 | I19: 기후_x000D_ 민수빈 | J19: 독서_x000D_ 배기연 | K19: 영어2_x000D_ 장지현 | L19: 미적_x000D_ 김동춘 | M19: 스포2_x000D_ 강은일 | N19: 스경기_x000D_ 강은일 | O19: 기후_x000D_ 민수빈 | P19: 독서_x000D_ 정수진 | Q19: 기후_x000D_ 민수빈 | R19: 영어2_x000D_ 장지현 | S19: _x000D_ | T19: 창체 | U19: 창체 | V19: 영어2_x000D_ 장지현 | W19: 미적_x000D_ 김동춘 | X19: 독어_x000D_ 박태호 | Y19: 국사2_x000D_ 김가향 | Z19: 미술_x000D_ 이경진 | AA19: 운동_x000D_ 강은일 | AB19: 스경기_x000D_ 강은일 | AC19: 운동_x000D_ 강은일 | AD19: 미적_x000D_ 김동춘 | AE19: 영어2_x000D_ 전은영 | AF19: 국사2_x000D_ 김가향 | AG19: 독서_x000D_ 박지빈 | AH19: 스포2_x000D_ 강은일 | AI19: 스경기_x000D_ 강은일
A20: 멀티 미디어실 | B20: _x000D_ | C20: _x000D_ | D20: _x000D_ | E20: _x000D_ | G20: _x000D_ | I20: _x000D_ | J20: 이동수업C | K20: _x000D_ | L20: _x000D_ | M20: _x000D_ | N20: _x000D_ | O20: 이동수업C | P20: _x000D_ | Q20: _x000D_ | R20: _x000D_ | S20: _x000D_ | T20: 창체 | U20: 창체 | V20: _x000D_ | W20: _x000D_ | X20: _x000D_ | Y20: _x000D_ | AA20: _x000D_ | AB20: _x000D_ | AC20: 이동수업C | AD20: _x000D_ | AE20: _x000D_ | AF20: _x000D_ | AG20: _x000D_ | AH20: _x000D_ | AI20: _x000D_
A21: 선택4실(210) | B21: _x000D_ | C21: _x000D_ | D21: _x000D_ | E21: _x000D_ | F21: 이동수업B | G21: _x000D_ | H21: 이동수업B | I21: _x000D_ | J21: 이동수업C | K21: _x000D_ | L21: 이동수업A | M21: _x000D_ | N21: _x000D_ | O21: 이동수업C | P21: _x000D_ | Q21: _x000D_ | R21: _x000D_ | S21: _x000D_ | T21: 창체 | U21: 창체 | V21: _x000D_ | W21: _x000D_ | X21: 이동수업A | Y21: _x000D_ | Z21: 이동수업B | AA21: _x000D_ | AB21: _x000D_ | AC21: 이동수업C | AD21: _x000D_ | AE21: 이동수업A | AF21: _x000D_ | AG21: _x000D_ | AH21: _x000D_ | AI21: _x000D_
A22: 선택3실(211) | B22: _x000D_ | C22: _x000D_ | D22: _x000D_ | E22: _x000D_ | F22: 이동수업B | G22: _x000D_ | H22: 이동수업B | I22: _x000D_ | J22: _x000D_ | K22: _x000D_ | L22: _x000D_ | M22: _x000D_ | N22: _x000D_ | O22: _x000D_ | P22: _x000D_ | Q22: _x000D_ | R22: _x000D_ | S22: _x000D_ | T22: 창체 | U22: 창체 | V22: _x000D_ | W22: _x000D_ | X22: _x000D_ | Y22: _x000D_ | Z22: 이동수업B | AA22: _x000D_ | AB22: _x000D_ | AC22: _x000D_ | AD22: _x000D_ | AE22: _x000D_ | AF22: _x000D_ | AG22: _x000D_ | AH22: _x000D_ | AI22: _x000D_
A23: 3학년1반 | B23: 이동수업N | C23: 공강_x000D_ 가상1 | D23: 이동수업K | E23: 이동수업L | F23: 진로_x000D_ 장지현 | G23: 이동수업O | H23: 이동수업K | I23: 이동수업O | J23: 진로_x000D_ 김이진 | K23: 이동수업L | L23: 국사_x000D_ 송영림 | M23: 이동수업M | N23: 당겨오기 수업 | O23: 이동수업O | P23: 이동수업L | Q23: 이동수업M | R23: 이동수업N | S23: 당겨오기 수업 | T23: 창체 | U23: 창체 | V23: 이동수업K | W23: 이동수업O | X23: 공강_x000D_ 가상2 | Y23: 스포_x000D_ 박은총 | Z23: 이동수업M | AA23: 이동수업N | AB23: 당겨오기 수업 | AC23: 이동수업K | AD23: 이동수업L | AE23: 스포_x000D_ 지청호 | AF23: 이동수업P | AG23: 이동수업M | AH23: 이동수업N | AI23: 미감비_x000D_ 이경진
A24: 3학년2반 | B24: 이동수업N | C24: 스포_x000D_ 지청호 | D24: 이동수업K | E24: 이동수업L | F24: 진로_x000D_ 김이진 | G24: 이동수업O | H24: 이동수업K | I24: 이동수업O | J24: 미감비_x000D_ 이경진 | K24: 이동수업L | L24: 공강_x000D_ 가상2 | M24: 이동수업M | N24: 당겨오기 수업 | O24: 이동수업O | P24: 이동수업L | Q24: 이동수업M | R24: 이동수업N | S24: 당겨오기 수업 | T24: 창체 | U24: 창체 | V24: 이동수업K | W24: 이동수업O | X24: 스포_x000D_ 박은총 | Y24: 진로_x000D_ 정혁준 | Z24: 이동수업M | AA24: 이동수업N | AB24: 당겨오기 수업 | AC24: 이동수업K | AD24: 이동수업L | AE24: 공강_x000D_ 가상1 | AF24: 이동수업P | AG24: 이동수업M | AH24: 이동수업N | AI24: 국사_x000D_ 송영림
A25: 3학년3반 | B25: 이동수업N | C25: 미감비_x000D_ 이경진 | D25: 이동수업K | E25: 이동수업L | F25: 공강_x000D_ 가상2 | G25: 이동수업O | H25: 이동수업K | I25: 이동수업O | J25: 스포_x000D_ 박은총 | K25: 이동수업L | L25: 진로_x000D_ 박미라 | M25: 이동수업M | N25: 당겨오기 수업 | O25: 이동수업O | P25: 이동수업L | Q25: 이동수업M | R25: 이동수업N | S25: 당겨오기 수업 | T25: 창체 | U25: 창체 | V25: 이동수업K | W25: 이동수업O | X25: 진로_x000D_ 김이진 | Y25: 공강_x000D_ 가상1 | Z25: 이동수업M | AA25: 이동수업N | AB25: 당겨오기 수업 | AC25: 이동수업K | AD25: 이동수업L | AE25: 국사_x000D_ 송영림 | AF25: 이동수업P | AG25: 이동수업M | AH25: 이동수업N | AI25: 스포_x000D_ 지청호
A26: 3학년4반 | B26: 이동수업N | C26: 진로_x000D_ 김이진 | D26: 이동수업K | E26: 이동수업L | F26: 스포_x000D_ 지청호 | G26: 이동수업O | H26: 이동수업K | I26: 이동수업O | J26: 공강_x000D_ 가상1 | K26: 이동수업L | L26: 미감비_x000D_ 이경진 | M26: 이동수업M | N26: 당겨오기 수업 | O26: 이동수업O | P26: 이동수업L | Q26: 이동수업M | R26: 이동수업N | S26: 당겨오기 수업 | T26: 창체 | U26: 창체 | V26: 이동수업K | W26: 이동수업O | X26: 국사_x000D_ 송영림 | Y26: 스포_x000D_ 신광현 | Z26: 이동수업M | AA26: 이동수업N | AB26: 당겨오기 수업 | AC26: 이동수업K | AD26: 이동수업L | AE26: 공강_x000D_ 가상2 | AF26: 이동수업P | AG26: 이동수업M | AH26: 이동수업N | AI26: 진로_x000D_ 박미라
A27: 3학년5반 | B27: 이동수업N | C27: 국사_x000D_ 송영림 | D27: 이동수업K | E27: 이동수업L | F27: 미감비_x000D_ 이경진 | G27: 이동수업O | H27: 이동수업K | I27: 이동수업O | J27: 스포_x000D_ 지청호 | K27: 이동수업L | L27: 진로_x000D_ 조낙원 | M27: 이동수업M | N27: 당겨오기 수업 | O27: 이동수업O | P27: 이동수업L | Q27: 이동수업M | R27: 이동수업N | S27: 당겨오기 수업 | T27: 창체 | U27: 창체 | V27: 이동수업K | W27: 이동수업O | X27: 진로_x000D_ 박영환 | Y27: 공강_x000D_ 가상3 | Z27: 이동수업M | AA27: 이동수업N | AB27: 당겨오기 수업 | AC27: 이동수업K | AD27: 이동수업L | AE27: 공강_x000D_ 가상4 | AF27: 이동수업P | AG27: 이동수업M | AH27: 이동수업N | AI27: 스포_x000D_ 신광현
A28: 3학년6반 | B28: 이동수업N | C28: 공강_x000D_ 가상4 | D28: 이동수업K | E28: 이동수업L | F28: 진로_x000D_ 박영환 | G28: 이동수업O | H28: 이동수업K | I28: 이동수업O | J28: 국사_x000D_ 송영림 | K28: 이동수업L | L28: 공강_x000D_ 가상3 | M28: 이동수업M | N28: 당겨오기 수업 | O28: 이동수업O | P28: 이동수업L | Q28: 이동수업M | R28: 이동수업N | S28: 당겨오기 수업 | T28: 창체 | U28: 창체 | V28: 이동수업K | W28: 이동수업O | X28: 미감비_x000D_ 이경진 | Y28: 스포_x000D_ 지청호 | Z28: 이동수업M | AA28: 이동수업N | AB28: 당겨오기 수업 | AC28: 이동수업K | AD28: 이동수업L | AE28: 스포_x000D_ 신광현 | AF28: 이동수업P | AG28: 이동수업M | AH28: 이동수업N | AI28: 진로_x000D_ 성아름
A29: 3학년7반 | B29: 이동수업N | C29: 공강_x000D_ 가상3 | D29: 이동수업K | E29: 이동수업L | F29: 국사_x000D_ 송영림 | G29: 이동수업O | H29: 이동수업K | I29: 이동수업O | J29: 진로_x000D_ 성아름 | K29: 이동수업L | L29: 스포_x000D_ 지청호 | M29: 이동수업M | N29: 당겨오기 수업 | O29: 이동수업O | P29: 이동수업L | Q29: 이동수업M | R29: 이동수업N | S29: 당겨오기 수업 | T29: 창체 | U29: 창체 | V29: 이동수업K | W29: 이동수업O | X29: 스포_x000D_ 신광현 | Y29: 미감비_x000D_ 박영환 | Z29: 이동수업M | AA29: 이동수업N | AB29: 당겨오기 수업 | AC29: 이동수업K | AD29: 이동수업L | AE29: 진로_x000D_ 이경진 | AF29: 이동수업P | AG29: 이동수업M | AH29: 이동수업N | AI29: 공강_x000D_ 가상4
A30: 3학년8반 | B30: 스개론_x000D_ 박승순 | C30: 스경체_x000D_ 신광현 | D30: 미감비_x000D_ 박영환 | E30: 스경체_x000D_ 신광현 | F30: 스경분_x000D_ 박승순 | G30: 스경실_x000D_ 신광현 | H30: 진로_x000D_ 장지현 | I30: 스경분_x000D_ 박승순 | J30: 재활_x000D_ 박승순 | K30: 스경체_x000D_ 신광현 | L30: 스개론_x000D_ 박승순 | M30: 스경분_x000D_ 박승순 | N30: _x000D_ | O30: 스경실_x000D_ 신광현 | P30: 진로_x000D_ 이경진 | Q30: 스경분_x000D_ 박승순 | R30: 스경체_x000D_ 신광현 | S30: 재활_x000D_ 박승순 | T30: 창체 | U30: 창체 | V30: 스경실_x000D_ 신광현 | W30: 재활_x000D_ 박승순 | X30: 공강_x000D_ 가상3 | Y30: 공강_x000D_ 가상4 | Z30: 스개론_x000D_ 박승순 | AA30: 스포_x000D_ 지청호 | AB30: _x000D_ | AC30: 국사_x000D_ 송영림 | AD30: 스포_x000D_ 지청호 | AE30: 공강_x000D_ 가상3 | AF30: 이동수업P | AG30: 재활_x000D_ 박승순 | AH30: 스경실_x000D_ 신광현 | AI30: 스개론_x000D_ 박승순
A31: 선택1실(309) | B31: 이동수업N | C31: _x000D_ | D31: 이동수업K | E31: 이동수업L | F31: _x000D_ | G31: 이동수업O | H31: 이동수업K | I31: 이동수업O | J31: _x000D_ | K31: 이동수업L | L31: _x000D_ | M31: 이동수업M | N31: _x000D_ | O31: 이동수업O | P31: 이동수업L | Q31: 이동수업M | R31: 이동수업N | S31: _x000D_ | T31: 창체 | U31: 창체 | V31: 이동수업K | W31: 이동수업O | X31: _x000D_ | Y31: _x000D_ | Z31: 이동수업M | AA31: 이동수업N | AB31: _x000D_ | AC31: 이동수업K | AD31: 이동수업L | AE31: _x000D_ | AF31: 이동수업P | AG31: 이동수업M | AH31: 이동수업N | AI31: _x000D_
A32: 선택2실(310) | B32: 이동수업N | C32: _x000D_ | D32: 이동수업K | E32: 이동수업L | F32: _x000D_ | G32: 이동수업O | H32: 이동수업K | I32: 이동수업O | J32: _x000D_ | K32: 이동수업L | L32: _x000D_ | M32: 이동수업M | N32: _x000D_ | O32: 이동수업O | P32: 이동수업L | Q32: 이동수업M | R32: 이동수업N | S32: _x000D_ | T32: 창체 | U32: 창체 | V32: 이동수업K | W32: 이동수업O | X32: _x000D_ | Y32: _x000D_ | Z32: 이동수업M | AA32: 이동수업N | AB32: _x000D_ | AC32: 이동수업K | AD32: 이동수업L | AE32: _x000D_ | AF32: 이동수업P | AG32: 이동수업M | AH32: 이동수업N | AI32: _x000D_
A33: 선택3실(311) | B33: 이동수업N | C33: _x000D_ | D33: _x000D_ | E33: 이동수업L | F33: _x000D_ | G33: _x000D_ | H33: _x000D_ | I33: _x000D_ | J33: _x000D_ | K33: 이동수업L | L33: _x000D_ | M33: _x000D_ | N33: _x000D_ | O33: _x000D_ | P33: 이동수업L | Q33: _x000D_ | R33: 이동수업N | S33: _x000D_ | T33: 창체 | U33: 창체 | V33: _x000D_ | W33: _x000D_ | X33: _x000D_ | Y33: _x000D_ | Z33: _x000D_ | AA33: 이동수업N | AB33: _x000D_ | AC33: _x000D_ | AD33: 이동수업L | AE33: _x000D_ | AF33: 이동수업P | AG33: _x000D_ | AH33: 이동수업N | AI33: _x000D_

Sheet 학급별 시간표
B2: 2026학년도 2학기 시간표
E3: 학 반 | F3: 3학년1반
C4: 월 | D4: 화 | E4: 수 | F4: 목 | G4: 금
B5: 1 | C5: =VLOOKUP($F$3,'전체학급시간표(학생용)'!$A$4:$AI$33,2,0) -> 이동수업N | D5: =VLOOKUP($F$3,'전체학급시간표(학생용)'!$A$4:$AI$33,8,0) -> 이동수업K | E5: =VLOOKUP($F$3,'전체학급시간표(학생용)'!$A$4:$AI$33,15,0) -> 이동수업O | F5: =VLOOKUP($F$3,'전체학급시간표(학생용)'!$A$4:$AI$33,22,0) -> 이동수업K | G5: =VLOOKUP($F$3,'전체학급시간표(학생용)'!$A$4:$AI$33,29,0) -> 이동수업K
B6: 2 | C6: =VLOOKUP($F$3,'전체학급시간표(학생용)'!$A$4:$AI$33,3,0) -> 공강_x000D_ 가상1 | D6: =VLOOKUP($F$3,'전체학급시간표(학생용)'!$A$4:$AI$33,9,0) -> 이동수업O | E6: =VLOOKUP($F$3,'전체학급시간표(학생용)'!$A$4:$AI$33,16,0) -> 이동수업L | F6: =VLOOKUP($F$3,'전체학급시간표(학생용)'!$A$4:$AI$33,23,0) -> 이동수업O | G6: =VLOOKUP($F$3,'전체학급시간표(학생용)'!$A$4:$AI$33,30,0) -> 이동수업L
B7: 3 | C7: =VLOOKUP($F$3,'전체학급시간표(학생용)'!$A$4:$AI$33,4,0) -> 이동수업K | D7: =VLOOKUP($F$3,'전체학급시간표(학생용)'!$A$4:$AI$33,10,0) -> 진로_x000D_ 김이진 | E7: =VLOOKUP($F$3,'전체학급시간표(학생용)'!$A$4:$AI$33,17,0) -> 이동수업M | F7: =VLOOKUP($F$3,'전체학급시간표(학생용)'!$A$4:$AI$33,24,0) -> 공강_x000D_ 가상2 | G7: =VLOOKUP($F$3,'전체학급시간표(학생용)'!$A$4:$AI$33,31,0) -> 스포_x000D_ 지청호
B8: 4 | C8: =VLOOKUP($F$3,'전체학급시간표(학생용)'!$A$4:$AI$33,5,0) -> 이동수업L | D8: =VLOOKUP($F$3,'전체학급시간표(학생용)'!$A$4:$AI$33,11,0) -> 이동수업L | E8: =VLOOKUP($F$3,'전체학급시간표(학생용)'!$A$4:$AI$33,18,0) -> 이동수업N | F8: =VLOOKUP($F$3,'전체학급시간표(학생용)'!$A$4:$AI$33,25,0) -> 스포_x000D_ 박은총 | G8: =VLOOKUP($F$3,'전체학급시간표(학생용)'!$A$4:$AI$33,32,0) -> 이동수업P
B9: 5 | C9: =VLOOKUP($F$3,'전체학급시간표(학생용)'!$A$4:$AI$33,6,0) -> 진로_x000D_ 장지현 | D9: =VLOOKUP($F$3,'전체학급시간표(학생용)'!$A$4:$AI$33,12,0) -> 국사_x000D_ 송영림 | E9: =VLOOKUP($F$3,'전체학급시간표(학생용)'!$A$4:$AI$33,19,0) -> 당겨오기 수업 | F9: =VLOOKUP($F$3,'전체학급시간표(학생용)'!$A$4:$AI$33,26,0) -> 이동수업M | G9: =VLOOKUP($F$3,'전체학급시간표(학생용)'!$A$4:$AI$33,33,0) -> 이동수업M
B10: 6 | C10: =VLOOKUP($F$3,'전체학급시간표(학생용)'!$A$4:$AI$33,7,0) -> 이동수업O | D10: =VLOOKUP($F$3,'전체학급시간표(학생용)'!$A$4:$AI$33,13,0) -> 이동수업M | E10: =VLOOKUP($F$3,'전체학급시간표(학생용)'!$A$4:$AI$33,20,0) -> 창체 | F10: =VLOOKUP($F$3,'전체학급시간표(학생용)'!$A$4:$AI$33,27,0) -> 이동수업N | G10: =VLOOKUP($F$3,'전체학급시간표(학생용)'!$A$4:$AI$33,34,0) -> 이동수업N
B11: 7 | D11: =VLOOKUP($F$3,'전체학급시간표(학생용)'!$A$4:$AI$33,14,0) -> 당겨오기 수업 | E11: =VLOOKUP($F$3,'전체학급시간표(학생용)'!$A$4:$AI$33,21,0) -> 창체 | F11: =VLOOKUP($F$3,'전체학급시간표(학생용)'!$A$4:$AI$33,28,0) -> 당겨오기 수업 | G11: =VLOOKUP($F$3,'전체학급시간표(학생용)'!$A$4:$AI$33,35,0) -> 미감비_x000D_ 이경진
